Workbook

Sheet 요약
A1: B3 ROI 요약 - 자동차 와이어 하네스 프리블록 작업장, 손 구성 셀 1기 (가상 고객 케이스)
A2: ="결론: 기본 시나리오(가정 시트 선택값)의 단순 회수 기간은 "&IF(ISNUMBER('계산'!C56),TEXT('계산'!C56,"0.0")&"년","회수 불가")&", 5년 NPV는 "&TEXT('계산'!C59/1000000,"#,##0")&"백만 원(할인율 "&TEXT('가정'!$D$83,"0%")&")이다. 이 가정이면 이렇다는 값이며, 인건비·속도비·교대·손 교체 단위에 따라 크게 달라진다. 모든 입력은 PoC와 고객 급여대장으로 교체해야 한다."
A4: 1. 시나리오별 결과 (계산 시트 D절 링크)
A5: 시나리오 | B5: 연간 절감 인건비 (원) | C5: 연간 운영비 (원) | D5: 연간 순효과 (원) | E5: 총 투자비 (원) | F5: 회수 기간 (년) | G5: 5년 NPV (원) | H5: 5년 내 회수?
A6: 기본 (가정 시트 선택값) | B6: ='계산'!C49 | C6: ='계산'!C54 | D6: ='계산'!C55 | E6: ='계산'!$C$27 | F6: ='계산'!C56 | G6: ='계산'!C59 | H6: ='계산'!C60
A7: 인건비 하한 | B7: ='계산'!D49 | C7: ='계산'!D54 | D7: ='계산'!D55 | E7: ='계산'!$C$27 | F7: ='계산'!D56 | G7: ='계산'!D59 | H7: ='계산'!D60
A8: 인건비 상한 | B8: ='계산'!E49 | C8: ='계산'!E54 | D8: ='계산'!E55 | E8: ='계산'!$C$27 | F8: ='계산'!E56 | G8: ='계산'!E59 | H8: ='계산'!E60
A9: 손 교체 낙관 (f1, 20%) | B9: ='계산'!F49 | C9: ='계산'!F54 | D9: ='계산'!F55 | E9: ='계산'!$C$27 | F9: ='계산'!F56 | G9: ='계산'!F59 | H9: ='계산'!F60
A10: 손 교체 보수 (f2, 100%) | B10: ='계산'!G49 | C10: ='계산'!G54 | D10: ='계산'!G55 | E10: ='계산'!$C$27 | F10: ='계산'!G56 | G10: ='계산'!G59 | H10: ='계산'!G60
A11: 손 교체 없음 (참고) | B11: ='계산'!H49 | C11: ='계산'!H54 | D11: ='계산'!H55 | E11: ='계산'!$C$27 | F11: ='계산'!H56 | G11: ='계산'!H59 | H11: ='계산'!H60
A12: 3교대 (f x1.5) | B12: ='계산'!I49 | C12: ='계산'!I54 | D12: ='계산'!I55 | E12: ='계산'!$C$27 | F12: ='계산'!I56 | G12: ='계산'!I59 | H12: ='계산'!I60
A13: 속도비 0.5 (PoC 게이트) | B13: ='계산'!J49 | C13: ='계산'!J54 | D13: ='계산'!J55 | E13: ='계산'!$C$27 | F13: ='계산'!J56 | G13: ='계산'!J59 | H13: ='계산'!J60
A14: 속도비 0.25 (시제품) | B14: ='계산'!K49 | C14: ='계산'!K54 | D14: ='계산'!K55 | E14: ='계산'!$C$27 | F14: ='계산'!K56 | G14: ='계산'!K59 | H14: ='계산'!K60
A16: 2. 구 가정 대비 (Q7 재현, 검산 시트)
A17: 구 가정(인건비 4,700만 원, 유지보수 10%)에서 교체비 0 회수 (년) | F17: ='계산'!N56
A18: 검산 불일치 건수 (0이어야 함) | F18: ='검산'!$C$42
A20: 3. 결과를 가장 크게 흔드는 변수 (민감도 시트 1절, NPV 폭 기준)
A21: ='민감도'!A5
A22: ='민감도'!A6
A24: 4. 5년 회수 조건
A25: 5년 회수에 필요한 연 순절감 (원) | F25: ='계산'!C28
A26: 기본 시나리오 연 순절감 (원) | F26: ='계산'!C55
A28: 5. 해석 주의
A29: - 속도비 0.5는 PoC의 기술 가능성 게이트(통과해야 사업 논의를 이어갈 수 있는 기술 기준)이며 ROI 성립 기준이 아니다. 0.5에서는 회수가 길어지거나 불가능하다.
A30: - 인건비는 공개된 1차 직접 자료가 없고 중소제조업 부품조립원 일급 등 대리 근거로 잡은 범위(하한 3,199만 ~ 상한 7,433만 원/인·년)다. 고객 급여대장으로 교체한다.
A31: - 손 교체는 공개 근거가 부족하다. 교체 빈도(f)보다 교체 단위(손 전체 대 모듈)가 회수를 더 크게 가른다. 모듈 교체 비용 20%는 산술 추정이다.
A32: - 라이선스(RLDX-1 상용 조건), 관리 인력, 전력, 초기 데이터·학습비는 미확인이라 0으로 두었다. 실제 값이 들어가면 회수는 길어진다.
A33: - 대체 인원은 속도비 x 성공률 x 가동률 x 교대 수의 단순 곱이다. 3교대 인건비는 2교대 평균과 같게 두었다(야간 비율 변화는 미반영).
A34: - 비재무 효과(회수 기간에 넣지 않음): 인력난 해소와 외국인력 의존 리스크 완화(하네스 업종에서는 Q1이 미검증), 품질 일관성, 야간 무인 가동, 숙련 암묵지의 데이터 자산화.
A36: 6. 손 단가 시나리오 - $23,000(제품 DB, 기본) 대 $7,500(RLWRLD 블로그) (B8, 민감도 시트 8절 링크)
A37: 손 단가는 견적 전까지 헤드라인에 반영하지 않는다. 두 값 모두 공식 견적이 아니며(추정) Tesollo 공식 견적으로 확정한다. 아래는 '이 단가라면 이렇다'는 민감도 비교이고, 기본 시나리오(위 1절)는 $23,000 그대로다. 연동 = 통합비가 하드웨어(손 포함)에 비례(현 모델), 비연동 = 통합비를 $23,000 기준 금액으로 고정.
A38: 손 교체 시나리오 | B38: 총 투자비 $23,000 (원) | C38: 총 투자비 $7,500 연동 (원) | D38: 총 투자비 $7,500 비연동 (원) | E38: 회수 $23,000 (년) | F38: 회수 $7,500 연동 (년) | G38: 회수 $7,500 비연동 (년) | H38: 회수 단축 연동 (년)
A39: 낙관 (f1, 20%) | B39: ='민감도'!B106 | C39: ='민감도'!C106 | D39: ='민감도'!C107 | E39: ='민감도'!B111 | F39: ='민감도'!C111 | G39: ='민감도'!C113 | H39: ='민감도'!D111
A40: 기본 (f2, 20%) | B40: ='민감도'!E106 | C40: ='민감도'!F106 | D40: ='민감도'!F107 | E40: ='민감도'!E111 | F40: ='민감도'!F111 | G40: ='민감도'!F113 | H40: ='민감도'!G111
A41: 보수 (f2, 100%) | B41: ='민감도'!H106 | C41: ='민감도'!I106 | D41: ='민감도'!I107 | E41: ='민감도'!H111 | F41: ='민감도'!I111 | G41: ='민감도'!I113 | H41: ='민감도'!J111
A43: 손 교체 시나리오 | B43: 5년 NPV $23,000 (원) | C43: 5년 NPV $7,500 연동 (원) | D43: 5년 NPV $7,500 비연동 (원) | E43: 손 소모비 $23,000 (원/년) | F43: 손 소모비 $7,500 (원/년) | G43: NPV 개선 연동 (원) | H43: NPV 개선 비연동 (원)
A44: 낙관 (f1, 20%) | B44: ='민감도'!B112 | C44: ='민감도'!C112 | D44: ='민감도'!C114 | E44: ='민감도'!B108 | F44: ='민감도'!C108 | G44: ='민감도'!D112 | H44: =D44-B44
A45: 기본 (f2, 20%) | B45: ='민감도'!E112 | C45: ='민감도'!F112 | D45: ='민감도'!F114 | E45: ='민감도'!E108 | F45: ='민감도'!F108 | G45: ='민감도'!G112 | H45: =D45-B45
A46: 보수 (f2, 100%) | B46: ='민감도'!H112 | C46: ='민감도'!I112 | D46: ='민감도'!I114 | E46: ='민감도'!H108 | F46: ='민감도'!I108 | G46: ='민감도'!J112 | H46: =D46-B46
A48: 손 대 그리퍼(Hand-E $7,250, 추정) 하드웨어 비교 | B48: 손 1개 단가비 $23,000 (배) | C48: 손 1개 단가비 $7,500 (배) | D48: 셀 하드웨어비 $23,000 (배) | E48: 셀 하드웨어비 $7,500 (배)
...

Sheet 가정
A1: B3 ROI 모델 - 가정 시트 (손 구성 셀 1기, 프리블록 작업장 1곳 기준)
A2: 파란 글씨 = 입력 셀(바꾸면 계산·민감도·검산 시트가 따라 바뀜). 통화 USD 또는 원(KRW), 환율·인건비 기준 2027년. 확인수준: 1차=정부·제조사 원문, 2차=기사·공고·블로그, 계산=소스 값으로 산출, 추정=근거 약함 또는 없음. 입력 우선순위: case/analysis.md 7절 기본 틀, 충돌 시 research/q7-hand-replacement.md(Q7)·q8-wage-inputs.md(Q8) 우선.
A4: ID | B4: 구분 | C4: 항목 | D4: 값 | E4: 단위 | F4: 근거 (출처 파일·절, URL) | G4: 확인수준
A5: 0. 시나리오 선택 (계산 시트 '기본' 열과 민감도 기준값이 이 선택을 따름)
A6: A01 | B6: 선택 | C6: 인건비 시나리오 (1=하한, 2=기본, 3=상한) | D6: 2 | E6: 번호 | F6: research/q8-wage-inputs.md 5절 | G6: 선택
A7: A02 | B7: 선택 | C7: 손 교체 시나리오 (1=낙관, 2=기본, 3=보수, 4=교체 없음[참고]) | D7: 2 | E7: 번호 | F7: research/q7-hand-replacement.md 6절 제안(낙관 f1·20%, 기본 f2·20%, 보수 f2·100%). 4번은 교체비 0 비교용 | G7: 선택
A8: 1. 현재 인력·공정
A9: A03 | B9: 공정 | C9: 셀 가동 교대 수 | D9: 2 | E9: 교대/일 | F9: case/analysis.md 7.4절 (2 기본, 3 상향 시나리오). 3교대는 로봇만 추가 가동 | G9: 추정
A10: A04 | B10: 공정 | C10: 연간 가동일 | D10: 250 | E10: 일/년 | F10: case/analysis.md 7.1절 (주 5일 x 50주). 참고 라인 [1]은 주 6일 | G10: 추정
A11: A05 | B11: 공정 | C11: 교대당 실가동 시간 | D11: 440 | E11: 분/교대 | F11: case/analysis.md 7.1절, reference/case--easychair-harness-line-balancing.md (참고 라인, 해외) | G11: 1차
A12: A06 | B12: 공정 | C12: 대체 대상 인원(교대당) | D12: 1 | E12: 명/교대 | F12: case/analysis.md 7.5절: 프리블록 작업장 1곳 = 교대당 1명 (7.4절 대체 인원 1.9 = 1.0 x 0.95 x 2 의 암묵 가정) | G12: 추정
A13: 2. 성능
A14: A07 | B14: 성능 | C14: 로봇 속도비 (로봇 처리량/사람 처리량) | D14: 1 | E14: 배 | F14: case/analysis.md 7.4절 (시나리오 0.25/0.5/1.0). 0.25는 전용 셀 시제품 '4배 빨라져야 동등' 역산 (reference/case--ams-cellios-automated-harness.md). 0.5는 PoC 기술 가능성 게이트이며 ROI 성립 기준이 아니다 | G14: 추정
A15: A08 | B15: 성능 | C15: 자동 처리 성공률 | D15: 0.95 | E15: % | F15: case/analysis.md 7.4절 (PoC 목표값, 시나리오 70/85/95). 공개 연구 55~90%대는 조건이 달라 직접 비교 불가 | G15: 추정
A16: A09 | B16: 성능 | C16: 가동률 | D16: 1 | E16: % | F16: case/analysis.md 7.5절은 가동률 항이 없어 100%로 암묵 적용(성공률이 재작업 손실을 흡수). 민감도에서 60~100%로 변화 | G16: 추정
A17: A10 | B17: 성능 | C17: 속도비 PoC 통과 게이트(기술 가능성 기준) | D17: 0.5 | E17: 배 | F17: case/analysis.md 7.5절 해석: 기술 가능성 게이트이며 ROI 기준 아님. 계산에는 쓰지 않고 요약 표시용 | G17: 추정
A18: 3. 인건비 (Q8 우선, 2027 기준, 원화)
A19: A11 | B19: 인건비 | C19: 통상시급 w - 하한 (2027 최저임금) | D19: 10700 | E19: 원/시간 | F19: research/q8-wage-inputs.md 1절. 고용노동부 보도자료 https://www.moel.go.kr/news/enews/report/enewsView.do?news_seq=19744 (reference/market--moel-minimum-wage-2027.md) | G19: 1차
A20: A12 | B20: 인건비 | C20: 통상시급 w - 기본 (부품조립원 일급 110,036원/8 x 1.037) | D20: 14263 | E20: 원/시간 | F20: research/q8-wage-inputs.md 5절. 중기중앙회 부품조립원 일급(2026-03) 헤럴드경제 https://www.heraldk.com/article/2026062819000081528 (reference/market--heraldk-sme-wage-2026h1.md). 하네스 조립원 직종 매핑 미확정 | G20: 추정
A21: A13 | B21: 인건비 | C21: 통상시급 w - 상한 (생산직 129개 직종 평균 일급 120,610원/8 x 1.037) | D21: 15634 | E21: 원/시간 | F21: research/q8-wage-inputs.md 5절. 같은 출처 (reference/market--heraldk-sme-wage-2026h1.md) | G21: 추정
A22: A14 | B22: 인건비 | C22: 야간조 인원 비율 p - 하한 | D22: 0 | E22: 비율 | F22: research/q8-wage-inputs.md 5절 (06~14/14~22시 편성, 야간 없음) | G22: 추정
A23: A15 | B23: 인건비 | C23: 야간조 인원 비율 p - 기본 | D23: 0.5 | E23: 비율 | F23: research/q8-wage-inputs.md 5절 (2교대 중 야간조 절반). 국내 하네스 사업장 교대 시각 미확인 | G23: 추정
A24: A16 | B24: 인건비 | C24: 야간조 인원 비율 p - 상한 | D24: 0.5 | E24: 비율 | F24: research/q8-wage-inputs.md 5절 | G24: 추정
A25: A17 | B25: 인건비 | C25: 월 연장근로 OT - 하한 | D25: 0 | E25: 시간/월 | F25: research/q8-wage-inputs.md 5절 | G25: 추정
A26: A18 | B26: 인건비 | C26: 월 연장근로 OT - 기본 (주 7.5시간 x 4.345주) | D26: 32.6 | E26: 시간/월 | F26: research/q8-wage-inputs.md 5절. 화성 하네스 조립·포장 공고 (reference/market--jobploy-hwaseong-harness-pack.md) | G26: 추정
A27: A19 | B27: 인건비 | C27: 월 연장근로 OT - 상한 (일 2시간 x 약 21.75일) | D27: 43.5 | E27: 시간/월 | F27: research/q8-wage-inputs.md 5절. 득영 공고, 비하네스 (reference/market--jobploy-deukyoung-2shift.md) | G27: 추정
A28: A20 | B28: 인건비 | C28: 월 소정근로 환산시간 (주 40시간 + 주휴 8시간) | D28: 209 | E28: 시간/월 | F28: research/q8-wage-inputs.md 1절. 고용노동부 보도자료 https://www.moel.go.kr/news/enews/report/enewsView.do?news_seq=19744 (reference/market--moel-minimum-wage-2027.md) | G28: 1차
A29: A21 | B29: 인건비 | C29: 월 실근로시간 (40시간 x 52주 / 12) | D29: 173.3 | E29: 시간/월 | F29: research/q8-wage-inputs.md 4절 (계산). 야간가산은 실근로 시간에만 적용 | G29: 계산
A30: A22 | B30: 인건비 | C30: 연장근로 가산 포함 배율 | D30: 1.5 | E30: 배 | F30: 근로기준법 제56조. reference/market--easylaw-working-hours-premium.md (research/q8 4절) | G30: 1차
... A44: A36 | B44: 인건비 | C44: [검산용 구 가정] 유지보수비 (하드웨어 전체 대비, 손 교체 포함 여부 미정의) | D44: 0.1 | E44: %/년 | F44: case/analysis.md 7.4절. Q7/Q8이 분리 필요로 판정(이중 계산). 검산에만 사용 | G44: 추정
A45: 4. 로봇 투자 (USD, 환율 1,400원)
A46: A37 | B46: 투자 | C46: 환율 | D46: 1400 | E46: 원/USD | F46: case/analysis.md 7절 머리말 (2025-04 기사 환산에서 역산, 기준일 환율 미반영). B3 실행 시 기준일 환율로 교체 필요 | G46: 추정
A47: A38 | B47: 투자 | C47: 협동로봇 팔 단가 (UR5e급, 범위 30,000~45,000) | D47: 37500 | E47: USD/대 | F47: case/analysis.md 7.3절 [31]. https://standardbots.com/blog/universal-robot-price (reference/hardware--ur-price-guide.md). 중간값은 추정 | G47: 2차
A48: A39 | B48: 투자 | C48: 팔 수 | D48: 2 | E48: 대 | F48: case/analysis.md 7.3절 (양팔 구성) | G48: 추정
A49: A40 | B49: 투자 | C49: 다관절 손(20-DoF) 단가 | D49: 23000 | E49: USD/개 | F49: case/analysis.md 7.3절 [32], research/q7 6-1절. https://humanoid.guide/product/dg-5f-s/ (reference/hardware--tesollo-dg5f-s.md). 제품 DB 표기 $23,000(기본 시나리오 유지). 충돌값: RLWRLD 블로그 약 $7,500(research/q9-allhandsup.md 7절, reference/hardware--allhandsup-blog-part2.md)은 D87에 시나리오로 입력. 둘 다 공식 견적 아님 - 추정. Tesollo 공식 견적으로 확정 전까지 헤드라인에 반영하지 않음. 이 셀 하나가 투자비·통합비·손 소모비를 모두 구동 | G49: 추정
A50: A41 | B50: 투자 | C50: 손 개수 | D50: 2 | E50: 개/셀 | F50: case/analysis.md 7.3절 | G50: 추정
A51: A42 | B51: 투자 | C51: 촉각 센서 단가 (GelSight Mini 대리값) | D51: 510 | E51: USD/개 | F51: case/analysis.md 7.3절 [35]. https://www.gelsight.com/product/gelsight-mini-system/ (reference/hardware--gelsight-mini.md). 대리값 | G51: 추정
A52: A43 | B52: 투자 | C52: 촉각 센서 수 (손끝 4 x 손 2) | D52: 8 | E52: 개 | F52: case/analysis.md 7.3절 | G52: 추정
A53: A44 | B53: 투자 | C53: 카메라 단가 (D455 대리값) | D53: 400 | E53: USD/대 | F53: case/analysis.md 7.3절 (research/hardware.md 4절, 검색 요약 가격) | G53: 추정
A54: A45 | B54: 투자 | C54: 카메라 수 | D54: 3 | E54: 대 | F54: case/analysis.md 7.3절 (근거 없음) | G54: 추정
...

Sheet 계산
A1: B3 ROI 모델 - 계산 시트 (모든 셀이 가정 시트를 참조하는 수식)
A3: A. 인건비 환산 (Q8 5절 식)
A4: 항목 | B4: 설명 | C4: 하한 | D4: 기본 | E4: 상한
A5: 통상시급 w (원/시간) | B5: 가정 시트 | C5: ='가정'!$D$19 | D5: ='가정'!$D$20 | E5: ='가정'!$D$21
A6: 야간조 비율 p | B6: 가정 시트 | C6: ='가정'!$D$22 | D6: ='가정'!$D$23 | E6: ='가정'!$D$24
A7: 월 연장근로 OT (시간) | B7: 가정 시트 | C7: ='가정'!$D$25 | D7: ='가정'!$D$26 | E7: ='가정'!$D$27
A8: 사업주 간접률 (4대보험+퇴직) | B8: 연금+건보+요양+실업+고안직능+산재+퇴직 | C8: ='가정'!$D$32+'가정'!$D$33+'가정'!$D$34+'가정'!$D$35+'가정'!$D$36+'가정'!$D$39+'가정'!$D$42 | D8: ='가정'!$D$32+'가정'!$D$33+'가정'!$D$34+'가정'!$D$35+'가정'!$D$37+'가정'!$D$40+'가정'!$D$42 | E8: ='가정'!$D$32+'가정'!$D$33+'가정'!$D$34+'가정'!$D$35+'가정'!$D$38+'가정'!$D$41+'가정'!$D$42
A9: 주간조 월 지급 (원) | B9: w x (209 + 1.5 x OT) | C9: =C5*('가정'!$D$28+'가정'!$D$30*C7) | D9: =D5*('가정'!$D$28+'가정'!$D$30*D7) | E9: =E5*('가정'!$D$28+'가정'!$D$30*E7)
A10: 야간조 월 지급 (원) | B10: w x (209 + 0.5 x 173.3 + 2.0 x OT) | C10: =C5*('가정'!$D$28+'가정'!$D$31*'가정'!$D$29+('가정'!$D$30+'가정'!$D$31)*C7) | D10: =D5*('가정'!$D$28+'가정'!$D$31*'가정'!$D$29+('가정'!$D$30+'가정'!$D$31)*D7) | E10: =E5*('가정'!$D$28+'가정'!$D$31*'가정'!$D$29+('가정'!$D$30+'가정'!$D$31)*E7)
A11: 2교대 평균 월 지급 (원) | B11: (1-p) x 주간 + p x 야간 | C11: =(1-C6)*C9+C6*C10 | D11: =(1-D6)*D9+D6*D10 | E11: =(1-E6)*E9+E6*E10
A12: 연 지급 (원) | B12: 12 x 평균 월 지급 | C12: =12*C11 | D12: =12*D11 | E12: =12*E11
A13: 연 인건비/인 (원, 간접률 포함) | B13: 연 지급 x (1+간접률). 2교대 평균, 1인 | C13: =C12*(1+C8) | D13: =D12*(1+D8) | E13: =E12*(1+E8)
A14: 선택된 인건비 시나리오의 연 인건비/인 (원) | B14: 가정 시트 선택값 | C14: =INDEX($C$13:$E$13,'가정'!$D$6)
A16: B. 투자비
A17: 항목 | B17: 설명 | C17: 값
A18: 팔 소계 (USD) | B18: 단가 x 대수 | C18: ='가정'!$D$47*'가정'!$D$48
A19: 손 소계 (USD) | B19: 단가 x 개수 | C19: ='가정'!$D$49*'가정'!$D$50
A20: 촉각 센서 소계 (USD) | C20: ='가정'!$D$51*'가정'!$D$52
A21: 카메라 소계 (USD) | C21: ='가정'!$D$53*'가정'!$D$54
A22: 손·팔 외 하드웨어 (USD) | B22: 촉각+카메라+지그+PC | C22: =C20+C21+'가정'!$D$55+'가정'!$D$56
A23: 하드웨어 합계 (USD) | B23: case/analysis.md 7.3절 141,280 | C23: =C18+C19+C22
A24: 손 제외 하드웨어 (USD) | B24: Q7 4절 95,280 (팔·시스템 유지보수 기준) | C24: =C23-C19
A25: 시스템 통합비 (USD) | B25: 하드웨어 x 통합비율 | C25: =C23*'가정'!$D$57
A26: 총 투자비 (USD) | B26: 하드웨어 + 통합비 (case/analysis.md 7.3절 282,560) | C26: =C23+C25
A27: 총 투자비 (원) | B27: USD x 환율 + 초기 데이터·학습비 (7.5절 395,584,000) | C27: =C26*'가정'!$D$46+'가정'!$D$58
A28: 5년 회수에 필요한 연 순절감 (원) | B28: 총 투자비 / 5 (7.5절 약 7,912만) | C28: =C27/'가정'!$D$84
A30: C. 그리퍼 대조군 정비 (참고, 합계 미포함 - 가정 6절)
A31: 항목 | B31: 설명 | C31: 값
A32: 정비 주기 - 빠른 경우 (년) | B32: 정비 사이클 / 연 사용 사이클 상한 (Q7 4절 약 1.2년) | C32: ='가정'!$D$78/'가정'!$D$80
A33: 정비 주기 - 느린 경우 (년) | B33: 정비 사이클 / 연 사용 사이클 하한 (약 2.4년) | C33: ='가정'!$D$78/'가정'!$D$79
A34: 연 정비비 상한 (원/년, 전체 그리퍼) | B34: 정비 1회 비용 입력 전에는 '가격 미입력' | C34: =IF(ISNUMBER('가정'!$D$81),'가정'!$D$77*'가정'!$D$81/C32,"가격 미입력")
A35: 연 정비비 하한 (원/년, 전체 그리퍼) | C35: =IF(ISNUMBER('가정'!$D$81),'가정'!$D$77*'가정'!$D$81/C33,"가격 미입력")
A36: 그리퍼 구성 하드웨어 (USD, F/T 센서 제외) | B36: 그리퍼 + 팔 + 카메라 + 지그 + PC (case/analysis.md 7.3절 105,700) | C36: ='가정'!$D$76*'가정'!$D$77+C18+C21+'가정'!$D$55+'가정'!$D$56
A38: D. 시나리오별 계산 (열 = 시나리오, 행 = 같은 수식). 파란 숫자는 시나리오 고유 입력
A39: 행 | B39: 설명 | C39: 기본 (가정 시트 선택값) | D39: 인건비 하한 | E39: 인건비 상한 | F39: 손 교체 낙관 (f1, 20%) | G39: 손 교체 보수 (f2, 100%) | H39: 손 교체 없음 (참고) | I39: 3교대 (f x1.5) | J39: 속도비 0.5 (PoC 게이트) | K39: 속도비 0.25 (시제품) | L39: [Q7 재현] N=1 손 전체 | M39: [Q7 재현] N=2 손 전체 | N39: [Q7 재현] 교체비 0 | O39: [Q7 재현] N=2 모듈 20% | P39: [Q7 재현] N=4 모듈 20% | Q39: [Q7 재현] 3교대 N=6 모듈 20% | R39: [7.5절 재현] 3교대 교체비 0 | S39: [7.5절 재현] 속도비 0.5 교체비 0
A40: 인건비 시나리오 번호 | B40: 1 하한 / 2 기본 / 3 상한 | C40: ='가정'!$D$6 | D40: 1 | E40: 3 | F40: ='가정'!$D$6 | G40: ='가정'!$D$6 | H40: ='가정'!$D$6 | I40: ='가정'!$D$6 | J40: ='가정'!$D$6 | K40: ='가정'!$D$6 | L40: 2 | M40: 2 | N40: 2 | O40: 2 | P40: 2 | Q40: 2 | R40: 2 | S40: 2
A41: 속도비 | C41: ='가정'!$D$14 | D41: ='가정'!$D$14 | E41: ='가정'!$D$14 | F41: ='가정'!$D$14 | G41: ='가정'!$D$14 | H41: ='가정'!$D$14 | I41: ='가정'!$D$14 | J41: 0.5 | K41: 0.25 | L41: 1 | M41: 1 | N41: 1 | O41: 1 | P41: 1 | Q41: 1 | R41: 1 | S41: 0.5
A42: 교대 수 | C42: ='가정'!$D$9 | D42: ='가정'!$D$9 | E42: ='가정'!$D$9 | F42: ='가정'!$D$9 | G42: ='가정'!$D$9 | H42: ='가정'!$D$9 | I42: 3 | J42: ='가정'!$D$9 | K42: ='가정'!$D$9 | L42: 2 | M42: 2 | N42: 2 | O42: 2 | P42: 2 | Q42: 3 | R42: 3 | S42: 2
A43: f: 손 1개당 연 교체 횟수 (2교대 기준) | B43: Q7 | C43: =CHOOSE('가정'!$D$7,'가정'!$D$64,'가정'!$D$66,'가정'!$D$68,'가정'!$D$70) | D43: =CHOOSE('가정'!$D$7,'가정'!$D$64,'가정'!$D$66,'가정'!$D$68,'가정'!$D$70) | E43: =CHOOSE('가정'!$D$7,'가정'!$D$64,'가정'!$D$66,'가정'!$D$68,'가정'!$D$70) | F43: ='가정'!$D$64 | G43: ='가정'!$D$68 | H43: ='가정'!$D$70 | I43: =CHOOSE('가정'!$D$7,'가정'!$D$64,'가정'!$D$66,'가정'!$D$68,'가정'!$D$70) | J43: =CHOOSE('가정'!$D$7,'가정'!$D$64,'가정'!$D$66,'가정'!$D$68,'가정'!$D$70) | K43: =CHOOSE('가정'!$D$7,'가정'!$D$64,'가정'!$D$66,'가정'!$D$68,'가정'!$D$70) | L43: 0.5 | M43: 1 | N43: 0 | O43: 1 | P43: 2 | Q43: 2 | R43: 0 | S43: 0
A44: 교체당 비용 비율 (손 가격 대비) | B44: Q7 | C44: =CHOOSE('가정'!$D$7,'가정'!$D$65,'가정'!$D$67,'가정'!$D$69,'가정'!$D$71) | D44: =CHOOSE('가정'!$D$7,'가정'!$D$65,'가정'!$D$67,'가정'!$D$69,'가정'!$D$71) | E44: =CHOOSE('가정'!$D$7,'가정'!$D$65,'가정'!$D$67,'가정'!$D$69,'가정'!$D$71) | F44: ='가정'!$D$65 | G44: ='가정'!$D$69 | H44: ='가정'!$D$71 | I44: =CHOOSE('가정'!$D$7,'가정'!$D$65,'가정'!$D$67,'가정'!$D$69,'가정'!$D$71) | J44: =CHOOSE('가정'!$D$7,'가정'!$D$65,'가정'!$D$67,'가정'!$D$69,'가정'!$D$71) | K44: =CHOOSE('가정'!$D$7,'가정'!$D$65,'가정'!$D$67,'가정'!$D$69,'가정'!$D$71) | L44: 1 | M44: 1 | N44: 0 | O44: 0.2 | P44: 0.2 | Q44: 0.2 | R44: 0 | S44: 0
...

Sheet 민감도
A1: B3 ROI 모델 - 민감도 시트 (모든 표는 수식, 축 값은 파란 입력)
A2: 기준값 = 가정 시트 선택 시나리오(인건비, 손 교체, 교대, 속도비). 표의 회수 기간 단위는 년, '회수 불가'는 연 순효과 0 이하. 초록 = 5년 이내 회수. 속도비 0.5는 PoC 기술 가능성 게이트이며 ROI 기준이 아니다.
A4: 결과를 가장 크게 흔드는 변수 (NPV 폭 기준, 아래 1절에서 자동 선정)
A5: ="1위: "&INDEX($A$9:$A$17,MATCH(1,$G$9:$G$17,0))&" (폭 "&TEXT(INDEX($F$9:$F$17,MATCH(1,$G$9:$G$17,0)),"#,##0")&" 백만원)"
A6: ="2위: "&INDEX($A$9:$A$17,MATCH(2,$G$9:$G$17,0))&" (폭 "&TEXT(INDEX($F$9:$F$17,MATCH(2,$G$9:$G$17,0)),"#,##0")&" 백만원)"
A7: 1. 변수별 영향 폭 (5년 NPV, 백만 원). 한 번에 한 변수만 바꾼 값
A8: 변수 | B8: 불리한 값 | C8: 유리한 값 | D8: NPV 불리 (백만원) | E8: NPV 유리 (백만원) | F8: 폭 (백만원) | G8: 순위
A9: 속도비 (로봇/사람) | B9: 0.5 | C9: 1.0 | D9: =((((1)*('계산'!$C$18+'계산'!$C$19)+'계산'!$C$22)*(1+('가정'!$D$57))*'가정'!$D$46+'가정'!$D$58)*-1+PV('가정'!$D$83,'가정'!$D$84,-('가정'!$D$12*(0.5)*('가정'!$D$15)*('가정'!$D$16)*('가정'!$D$9)*('계산'!$C$14)-((1)*'계산'!$C$18+'계산'!$C$22)*('가정'!$D$60)*'가정'!$D$46-'가정'!$D$50*(CHOOSE('가정'!$D$7,'가정'!$D$64,'가정'!$D$66,'가정'!$D$68,'가정'!$D$70))*('가정'!$D$9)/'가정'!$D$63*(CHOOSE('가정'!$D$7,'가정'!$D$65,'가정'!$D$67,'가정'!$D$69,'가정'!$D$71))*'가정'!$D$49*(1)*'가정'!$D$46-('가정'!$D$72+'가정'!$D$73+'가정'!$D$74))))/1000000 | E9: =((((1)*('계산'!$C$18+'계산'!$C$19)+'계산'!$C$22)*(1+('가정'!$D$57))*'가정'!$D$46+'가정'!$D$58)*-1+PV('가정'!$D$83,'가정'!$D$84,-('가정'!$D$12*(1)*('가정'!$D$15)*('가정'!$D$16)*('가정'!$D$9)*('계산'!$C$14)-((1)*'계산'!$C$18+'계산'!$C$22)*('가정'!$D$60)*'가정'!$D$46-'가정'!$D$50*(CHOOSE('가정'!$D$7,'가정'!$D$64,'가정'!$D$66,'가정'!$D$68,'가정'!$D$70))*('가정'!$D$9)/'가정'!$D$63*(CHOOSE('가정'!$D$7,'가정'!$D$65,'가정'!$D$67,'가정'!$D$69,'가정'!$D$71))*'가정'!$D$49*(1)*'가정'!$D$46-('가정'!$D$72+'가정'!$D$73+'가정'!$D$74))))/1000000 | F9: =ABS(E9-D9) | G9: =RANK(F9,$F$9:$F$17)
A10: 인건비 시나리오 (시급, 야간, 연장) | B10: 하한 | C10: 상한 | D10: =((((1)*('계산'!$C$18+'계산'!$C$19)+'계산'!$C$22)*(1+('가정'!$D$57))*'가정'!$D$46+'가정'!$D$58)*-1+PV('가정'!$D$83,'가정'!$D$84,-('가정'!$D$12*('가정'!$D$14)*('가정'!$D$15)*('가정'!$D$16)*('가정'!$D$9)*(INDEX('계산'!$C$13:$E$13,1))-((1)*'계산'!$C$18+'계산'!$C$22)*('가정'!$D$60)*'가정'!$D$46-'가정'!$D$50*(CHOOSE('가정'!$D$7,'가정'!$D$64,'가정'!$D$66,'가정'!$D$68,'가정'!$D$70))*('가정'!$D$9)/'가정'!$D$63*(CHOOSE('가정'!$D$7,'가정'!$D$65,'가정'!$D$67,'가정'!$D$69,'가정'!$D$71))*'가정'!$D$49*(1)*'가정'!$D$46-('가정'!$D$72+'가정'!$D$73+'가정'!$D$74))))/1000000 | E10: =((((1)*('계산'!$C$18+'계산'!$C$19)+'계산'!$C$22)*(1+('가정'!$D$57))*'가정'!$D$46+'가정'!$D$58)*-1+PV('가정'!$D$83,'가정'!$D$84,-('가정'!$D$12*('가정'!$D$14)*('가정'!$D$15)*('가정'!$D$16)*('가정'!$D$9)*(INDEX('계산'!$C$13:$E$13,3))-((1)*'계산'!$C$18+'계산'!$C$22)*('가정'!$D$60)*'가정'!$D$46-'가정'!$D$50*(CHOOSE('가정'!$D$7,'가정'!$D$64,'가정'!$D$66,'가정'!$D$68,'가정'!$D$70))*('가정'!$D$9)/'가정'!$D$63*(CHOOSE('가정'!$D$7,'가정'!$D$65,'가정'!$D$67,'가정'!$D$69,'가정'!$D$71))*'가정'!$D$49*(1)*'가정'!$D$46-('가정'!$D$72+'가정'!$D$73+'가정'!$D$74))))/1000000 | F10: =ABS(E10-D10) | G10: =RANK(F10,$F$9:$F$17)
A11: 손 교체 (f x 교체당 비율) | B11: 보수 f2·100% | C11: 낙관 f1·20% | D11: =((((1)*('계산'!$C$18+'계산'!$C$19)+'계산'!$C$22)*(1+('가정'!$D$57))*'가정'!$D$46+'가정'!$D$58)*-1+PV('가정'!$D$83,'가정'!$D$84,-('가정'!$D$12*('가정'!$D$14)*('가정'!$D$15)*('가정'!$D$16)*('가정'!$D$9)*('계산'!$C$14)-((1)*'계산'!$C$18+'계산'!$C$22)*('가정'!$D$60)*'가정'!$D$46-'가정'!$D$50*(CHOOSE(3,'가정'!$D$64,'가정'!$D$66,'가정'!$D$68,'가정'!$D$70))*('가정'!$D$9)/'가정'!$D$63*(CHOOSE(3,'가정'!$D$65,'가정'!$D$67,'가정'!$D$69,'가정'!$D$71))*'가정'!$D$49*(1)*'가정'!$D$46-('가정'!$D$72+'가정'!$D$73+'가정'!$D$74))))/1000000 | E11: =((((1)*('계산'!$C$18+'계산'!$C$19)+'계산'!$C$22)*(1+('가정'!$D$57))*'가정'!$D$46+'가정'!$D$58)*-1+PV('가정'!$D$83,'가정'!$D$84,-('가정'!$D$12*('가정'!$D$14)*('가정'!$D$15)*('가정'!$D$16)*('가정'!$D$9)*('계산'!$C$14)-((1)*'계산'!$C$18+'계산'!$C$22)*('가정'!$D$60)*'가정'!$D$46-'가정'!$D$50*(CHOOSE(1,'가정'!$D$64,'가정'!$D$66,'가정'!$D$68,'가정'!$D$70))*('가정'!$D$9)/'가정'!$D$63*(CHOOSE(1,'가정'!$D$65,'가정'!$D$67,'가정'!$D$69,'가정'!$D$71))*'가정'!$D$49*(1)*'가정'!$D$46-('가정'!$D$72+'가정'!$D$73+'가정'!$D$74))))/1000000 | F11: =ABS(E11-D11) | G11: =RANK(F11,$F$9:$F$17)
A12: 교대 수 | B12: 2교대 | C12: 3교대 | D12: =((((1)*('계산'!$C$18+'계산'!$C$19)+'계산'!$C$22)*(1+('가정'!$D$57))*'가정'!$D$46+'가정'!$D$58)*-1+PV('가정'!$D$83,'가정'!$D$84,-('가정'!$D$12*('가정'!$D$14)*('가정'!$D$15)*('가정'!$D$16)*(2)*('계산'!$C$14)-((1)*'계산'!$C$18+'계산'!$C$22)*('가정'!$D$60)*'가정'!$D$46-'가정'!$D$50*(CHOOSE('가정'!$D$7,'가정'!$D$64,'가정'!$D$66,'가정'!$D$68,'가정'!$D$70))*(2)/'가정'!$D$63*(CHOOSE('가정'!$D$7,'가정'!$D$65,'가정'!$D$67,'가정'!$D$69,'가정'!$D$71))*'가정'!$D$49*(1)*'가정'!$D$46-('가정'!$D$72+'가정'!$D$73+'가정'!$D$74))))/1000000 | E12: =((((1)*('계산'!$C$18+'계산'!$C$19)+'계산'!$C$22)*(1+('가정'!$D$57))*'가정'!$D$46+'가정'!$D$58)*-1+PV('가정'!$D$83,'가정'!$D$84,-('가정'!$D$12*('가정'!$D$14)*('가정'!$D$15)*('가정'!$D$16)*(3)*('계산'!$C$14)-((1)*'계산'!$C$18+'계산'!$C$22)*('가정'!$D$60)*'가정'!$D$46-'가정'!$D$50*(CHOOSE('가정'!$D$7,'가정'!$D$64,'가정'!$D$66,'가정'!$D$68,'가정'!$D$70))*(3)/'가정'!$D$63*(CHOOSE('가정'!$D$7,'가정'!$D$65,'가정'!$D$67,'가정'!$D$69,'가정'!$D$71))*'가정'!$D$49*(1)*'가정'!$D$46-('가정'!$D$72+'가정'!$D$73+'가정'!$D$74))))/1000000 | F12: =ABS(E12-D12) | G12: =RANK(F12,$F$9:$F$17)
A13: 성공률 | B13: 70% | C13: 95% | D13: =((((1)*('계산'!$C$18+'계산'!$C$19)+'계산'!$C$22)*(1+('가정'!$D$57))*'가정'!$D$46+'가정'!$D$58)*-1+PV('가정'!$D$83,'가정'!$D$84,-('가정'!$D$12*('가정'!$D$14)*(0.7)*('가정'!$D$16)*('가정'!$D$9)*('계산'!$C$14)-((1)*'계산'!$C$18+'계산'!$C$22)*('가정'!$D$60)*'가정'!$D$46-'가정'!$D$50*(CHOOSE('가정'!$D$7,'가정'!$D$64,'가정'!$D$66,'가정'!$D$68,'가정'!$D$70))*('가정'!$D$9)/'가정'!$D$63*(CHOOSE('가정'!$D$7,'가정'!$D$65,'가정'!$D$67,'가정'!$D$69,'가정'!$D$71))*'가정'!$D$49*(1)*'가정'!$D$46-('가정'!$D$72+'가정'!$D$73+'가정'!$D$74))))/1000000 | E13: =((((1)*('계산'!$C$18+'계산'!$C$19)+'계산'!$C$22)*(1+('가정'!$D$57))*'가정'!$D$46+'가정'!$D$58)*-1+PV('가정'!$D$83,'가정'!$D$84,-('가정'!$D$12*('가정'!$D$14)*(0.95)*('가정'!$D$16)*('가정'!$D$9)*('계산'!$C$14)-((1)*'계산'!$C$18+'계산'!$C$22)*('가정'!$D$60)*'가정'!$D$46-'가정'!$D$50*(CHOOSE('가정'!$D$7,'가정'!$D$64,'가정'!$D$66,'가정'!$D$68,'가정'!$D$70))*('가정'!$D$9)/'가정'!$D$63*(CHOOSE('가정'!$D$7,'가정'!$D$65,'가정'!$D$67,'가정'!$D$69,'가정'!$D$71))*'가정'!$D$49*(1)*'가정'!$D$46-('가정'!$D$72+'가정'!$D$73+'가정'!$D$74))))/1000000 | F13: =ABS(E13-D13) | G13: =RANK(F13,$F$9:$F$17)
A14: 가동률 | B14: 60% | C14: 100% | D14: =((((1)*('계산'!$C$18+'계산'!$C$19)+'계산'!$C$22)*(1+('가정'!$D$57))*'가정'!$D$46+'가정'!$D$58)*-1+PV('가정'!$D$83,'가정'!$D$84,-('가정'!$D$12*('가정'!$D$14)*('가정'!$D$15)*(0.6)*('가정'!$D$9)*('계산'!$C$14)-((1)*'계산'!$C$18+'계산'!$C$22)*('가정'!$D$60)*'가정'!$D$46-'가정'!$D$50*(CHOOSE('가정'!$D$7,'가정'!$D$64,'가정'!$D$66,'가정'!$D$68,'가정'!$D$70))*('가정'!$D$9)/'가정'!$D$63*(CHOOSE('가정'!$D$7,'가정'!$D$65,'가정'!$D$67,'가정'!$D$69,'가정'!$D$71))*'가정'!$D$49*(1)*'가정'!$D$46-('가정'!$D$72+'가정'!$D$73+'가정'!$D$74))))/1000000 | E14: =((((1)*('계산'!$C$18+'계산'!$C$19)+'계산'!$C$22)*(1+('가정'!$D$57))*'가정'!$D$46+'가정'!$D$58)*-1+PV('가정'!$D$83,'가정'!$D$84,-('가정'!$D$12*('가정'!$D$14)*('가정'!$D$15)*(1)*('가정'!$D$9)*('계산'!$C$14)-((1)*'계산'!$C$18+'계산'!$C$22)*('가정'!$D$60)*'가정'!$D$46-'가정'!$D$50*(CHOOSE('가정'!$D$7,'가정'!$D$64,'가정'!$D$66,'가정'!$D$68,'가정'!$D$70))*('가정'!$D$9)/'가정'!$D$63*(CHOOSE('가정'!$D$7,'가정'!$D$65,'가정'!$D$67,'가정'!$D$69,'가정'!$D$71))*'가정'!$D$49*(1)*'가정'!$D$46-('가정'!$D$72+'가정'!$D$73+'가정'!$D$74))))/1000000 | F14: =ABS(E14-D14) | G14: =RANK(F14,$F$9:$F$17)
A15: 로봇 팔·손 단가 | B15: +30% | C15: -30% | D15: =((((1.3)*('계산'!$C$18+'계산'!$C$19)+'계산'!$C$22)*(1+('가정'!$D$57))*'가정'!$D$46+'가정'!$D$58)*-1+PV('가정'!$D$83,'가정'!$D$84,-('가정'!$D$12*('가정'!$D$14)*('가정'!$D$15)*('가정'!$D$16)*('가정'!$D$9)*('계산'!$C$14)-((1.3)*'계산'!$C$18+'계산'!$C$22)*('가정'!$D$60)*'가정'!$D$46-'가정'!$D$50*(CHOOSE('가정'!$D$7,'가정'!$D$64,'가정'!$D$66,'가정'!$D$68,'가정'!$D$70))*('가정'!$D$9)/'가정'!$D$63*(CHOOSE('가정'!$D$7,'가정'!$D$65,'가정'!$D$67,'가정'!$D$69,'가정'!$D$71))*'가정'!$D$49*(1.3)*'가정'!$D$46-('가정'!$D$72+'가정'!$D$73+'가정'!$D$74))))/1000000 | E15: =((((0.7)*('계산'!$C$18+'계산'!$C$19)+'계산'!$C$22)*(1+('가정'!$D$57))*'가정'!$D$46+'가정'!$D$58)*-1+PV('가정'!$D$83,'가정'!$D$84,-('가정'!$D$12*('가정'!$D$14)*('가정'!$D$15)*('가정'!$D$16)*('가정'!$D$9)*('계산'!$C$14)-((0.7)*'계산'!$C$18+'계산'!$C$22)*('가정'!$D$60)*'가정'!$D$46-'가정'!$D$50*(CHOOSE('가정'!$D$7,'가정'!$D$64,'가정'!$D$66,'가정'!$D$68,'가정'!$D$70))*('가정'!$D$9)/'가정'!$D$63*(CHOOSE('가정'!$D$7,'가정'!$D$65,'가정'!$D$67,'가정'!$D$69,'가정'!$D$71))*'가정'!$D$49*(0.7)*'가정'!$D$46-('가정'!$D$72+'가정'!$D$73+'가정'!$D$74))))/1000000 | F15: =ABS(E15-D15) | G15: =RANK(F15,$F$9:$F$17)
A16: 시스템 통합비율 | B16: 200% | C16: 50% | D16: =((((1)*('계산'!$C$18+'계산'!$C$19)+'계산'!$C$22)*(1+(2))*'가정'!$D$46+'가정'!$D$58)*-1+PV('가정'!$D$83,'가정'!$D$84,-('가정'!$D$12*('가정'!$D$14)*('가정'!$D$15)*('가정'!$D$16)*('가정'!$D$9)*('계산'!$C$14)-((1)*'계산'!$C$18+'계산'!$C$22)*('가정'!$D$60)*'가정'!$D$46-'가정'!$D$50*(CHOOSE('가정'!$D$7,'가정'!$D$64,'가정'!$D$66,'가정'!$D$68,'가정'!$D$70))*('가정'!$D$9)/'가정'!$D$63*(CHOOSE('가정'!$D$7,'가정'!$D$65,'가정'!$D$67,'가정'!$D$69,'가정'!$D$71))*'가정'!$D$49*(1)*'가정'!$D$46-('가정'!$D$72+'가정'!$D$73+'가정'!$D$74))))/1000000 | E16: =((((1)*('계산'!$C$18+'계산'!$C$19)+'계산'!$C$22)*(1+(0.5))*'가정'!$D$46+'가정'!$D$58)*-1+PV('가정'!$D$83,'가정'!$D$84,-('가정'!$D$12*('가정'!$D$14)*('가정'!$D$15)*('가정'!$D$16)*('가정'!$D$9)*('계산'!$C$14)-((1)*'계산'!$C$18+'계산'!$C$22)*('가정'!$D$60)*'가정'!$D$46-'가정'!$D$50*(CHOOSE('가정'!$D$7,'가정'!$D$64,'가정'!$D$66,'가정'!$D$68,'가정'!$D$70))*('가정'!$D$9)/'가정'!$D$63*(CHOOSE('가정'!$D$7,'가정'!$D$65,'가정'!$D$67,'가정'!$D$69,'가정'!$D$71))*'가정'!$D$49*(1)*'가정'!$D$46-('가정'!$D$72+'가정'!$D$73+'가정'!$D$74))))/1000000 | F16: =ABS(E16-D16) | G16: =RANK(F16,$F$9:$F$17)
A17: 팔·시스템 유지보수율 | B17: 8% | C17: 3% | D17: =((((1)*('계산'!$C$18+'계산'!$C$19)+'계산'!$C$22)*(1+('가정'!$D$57))*'가정'!$D$46+'가정'!$D$58)*-1+PV('가정'!$D$83,'가정'!$D$84,-('가정'!$D$12*('가정'!$D$14)*('가정'!$D$15)*('가정'!$D$16)*('가정'!$D$9)*('계산'!$C$14)-((1)*'계산'!$C$18+'계산'!$C$22)*('가정'!$D$62)*'가정'!$D$46-'가정'!$D$50*(CHOOSE('가정'!$D$7,'가정'!$D$64,'가정'!$D$66,'가정'!$D$68,'가정'!$D$70))*('가정'!$D$9)/'가정'!$D$63*(CHOOSE('가정'!$D$7,'가정'!$D$65,'가정'!$D$67,'가정'!$D$69,'가정'!$D$71))*'가정'!$D$49*(1)*'가정'!$D$46-('가정'!$D$72+'가정'!$D$73+'가정'!$D$74))))/1000000 | E17: =((((1)*('계산'!$C$18+'계산'!$C$19)+'계산'!$C$22)*(1+('가정'!$D$57))*'가정'!$D$46+'가정'!$D$58)*-1+PV('가정'!$D$83,'가정'!$D$84,-('가정'!$D$12*('가정'!$D$14)*('가정'!$D$15)*('가정'!$D$16)*('가정'!$D$9)*('계산'!$C$14)-((1)*'계산'!$C$18+'계산'!$C$22)*('가정'!$D$61)*'가정'!$D$46-'가정'!$D$50*(CHOOSE('가정'!$D$7,'가정'!$D$64,'가정'!$D$66,'가정'!$D$68,'가정'!$D$70))*('가정'!$D$9)/'가정'!$D$63*(CHOOSE('가정'!$D$7,'가정'!$D$65,'가정'!$D$67,'가정'!$D$69,'가정'!$D$71))*'가정'!$D$49*(1)*'가정'!$D$46-('가정'!$D$72+'가정'!$D$73+'가정'!$D$74))))/1000000 | F17: =ABS(E17-D17) | G17: =RANK(F17,$F$9:$F$17)
A18: 기준(기본) NPV (백만원) | D18: ='계산'!$C$59/1000000
A21: 2. 속도비 x 인건비 시나리오 - 회수 기간 (년)
A22: 기준: 가정 시트 선택 손 교체·교대. 인건비 시나리오 1=하한 2=기본 3=상한. 속도비 0.5는 기술 가능성 게이트일 뿐 ROI 성립 기준이 아니다.
A23: 속도비 \ 인건비 시나리오 | B23: 1 | C23: 2 | D23: 3
A24: 0.25 | B24: =IF(('가정'!$D$12*($A24)*('가정'!$D$15)*('가정'!$D$16)*('가정'!$D$9)*(INDEX('계산'!$C$13:$E$13,B$23))-((1)*'계산'!$C$18+'계산'!$C$22)*('가정'!$D$60)*'가정'!$D$46-'가정'!$D$50*(CHOOSE('가정'!$D$7,'가정'!$D$64,'가정'!$D$66,'가정'!$D$68,'가정'!$D$70))*('가정'!$D$9)/'가정'!$D$63*(CHOOSE('가정'!$D$7,'가정'!$D$65,'가정'!$D$67,'가정'!$D$69,'가정'!$D$71))*'가정'!$D$49*(1)*'가정'!$D$46-('가정'!$D$72+'가정'!$D$73+'가정'!$D$74))>0,(((1)*('계산'!$C$18+'계산'!$C$19)+'계산'!$C$22)*(1+('가정'!$D$57))*'가정'!$D$46+'가정'!$D$58)/('가정'!$D$12*($A24)*('가정'!$D$15)*('가정'!$D$16)*('가정'!$D$9)*(INDEX('계산'!$C$13:$E$13,B$23))-((1)*'계산'!$C$18+'계산'!$C$22)*('가정'!$D$60)*'가정'!$D$46-'가정'!$D$50*(CHOOSE('가정'!$D$7,'가정'!$D$64,'가정'!$D$66,'가정'!$D$68,'가정'!$D$70))*('가정'!$D$9)/'가정'!$D$63*(CHOOSE('가정'!$D$7,'가정'!$D$65,'가정'!$D$67,'가정'!$D$69,'가정'!$D$71))*'가정'!$D$49*(1)*'가정'!$D$46-('가정'!$D$72+'가정'!$D$73+'가정'!$D$74)),"회수 불가") | C24: =IF(('가정'!$D$12*($A24)*('가정'!$D$15)*('가정'!$D$16)*('가정'!$D$9)*(INDEX('계산'!$C$13:$E$13,C$23))-((1)*'계산'!$C$18+'계산'!$C$22)*('가정'!$D$60)*'가정'!$D$46-'가정'!$D$50*(CHOOSE('가정'!$D$7,'가정'!$D$64,'가정'!$D$66,'가정'!$D$68,'가정'!$D$70))*('가정'!$D$9)/'가정'!$D$63*(CHOOSE('가정'!$D$7,'가정'!$D$65,'가정'!$D$67,'가정'!$D$69,'가정'!$D$71))*'가정'!$D$49*(1)*'가정'!$D$46-('가정'!$D$72+'가정'!$D$73+'가정'!$D$74))>0,(((1)*('계산'!$C$18+'계산'!$C$19)+'계산'!$C$22)*(1+('가정'!$D$57))*'가정'!$D$46+'가정'!$D$58)/('가정'!$D$12*($A24)*('가정'!$D$15)*('가정'!$D$16)*('가정'!$D$9)*(INDEX('계산'!$C$13:$E$13,C$23))-((1)*'계산'!$C$18+'계산'!$C$22)*('가정'!$D$60)*'가정'!$D$46-'가정'!$D$50*(CHOOSE('가정'!$D$7,'가정'!$D$64,'가정'!$D$66,'가정'!$D$68,'가정'!$D$70))*('가정'!$D$9)/'가정'!$D$63*(CHOOSE('가정'!$D$7,'가정'!$D$65,'가정'!$D$67,'가정'!$D$69,'가정'!$D$71))*'가정'!$D$49*(1)*'가정'!$D$46-('가정'!$D$72+'가정'!$D$73+'가정'!$D$74)),"회수 불가") | D24: =IF(('가정'!$D$12*($A24)*('가정'!$D$15)*('가정'!$D$16)*('가정'!$D$9)*(INDEX('계산'!$C$13:$E$13,D$23))-((1)*'계산'!$C$18+'계산'!$C$22)*('가정'!$D$60)*'가정'!$D$46-'가정'!$D$50*(CHOOSE('가정'!$D$7,'가정'!$D$64,'가정'!$D$66,'가정'!$D$68,'가정'!$D$70))*('가정'!$D$9)/'가정'!$D$63*(CHOOSE('가정'!$D$7,'가정'!$D$65,'가정'!$D$67,'가정'!$D$69,'가정'!$D$71))*'가정'!$D$49*(1)*'가정'!$D$46-('가정'!$D$72+'가정'!$D$73+'가정'!$D$74))>0,(((1)*('계산'!$C$18+'계산'!$C$19)+'계산'!$C$22)*(1+('가정'!$D$57))*'가정'!$D$46+'가정'!$D$58)/('가정'!$D$12*($A24)*('가정'!$D$15)*('가정'!$D$16)*('가정'!$D$9)*(INDEX('계산'!$C$13:$E$13,D$23))-((1)*'계산'!$C$18+'계산'!$C$22)*('가정'!$D$60)*'가정'!$D$46-'가정'!$D$50*(CHOOSE('가정'!$D$7,'가정'!$D$64,'가정'!$D$66,'가정'!$D$68,'가정'!$D$70))*('가정'!$D$9)/'가정'!$D$63*(CHOOSE('가정'!$D$7,'가정'!$D$65,'가정'!$D$67,'가정'!$D$69,'가정'!$D$71))*'가정'!$D$49*(1)*'가정'!$D$46-('가정'!$D$72+'가정'!$D$73+'가정'!$D$74)),"회수 불가")
A25: 0.5 | B25: =IF(('가정'!$D$12*($A25)*('가정'!$D$15)*('가정'!$D$16)*('가정'!$D$9)*(INDEX('계산'!$C$13:$E$13,B$23))-((1)*'계산'!$C$18+'계산'!$C$22)*('가정'!$D$60)*'가정'!$D$46-'가정'!$D$50*(CHOOSE('가정'!$D$7,'가정'!$D$64,'가정'!$D$66,'가정'!$D$68,'가정'!$D$70))*('가정'!$D$9)/'가정'!$D$63*(CHOOSE('가정'!$D$7,'가정'!$D$65,'가정'!$D$67,'가정'!$D$69,'가정'!$D$71))*'가정'!$D$49*(1)*'가정'!$D$46-('가정'!$D$72+'가정'!$D$73+'가정'!$D$74))>0,(((1)*('계산'!$C$18+'계산'!$C$19)+'계산'!$C$22)*(1+('가정'!$D$57))*'가정'!$D$46+'가정'!$D$58)/('가정'!$D$12*($A25)*('가정'!$D$15)*('가정'!$D$16)*('가정'!$D$9)*(INDEX('계산'!$C$13:$E$13,B$23))-((1)*'계산'!$C$18+'계산'!$C$22)*('가정'!$D$60)*'가정'!$D$46-'가정'!$D$50*(CHOOSE('가정'!$D$7,'가정'!$D$64,'가정'!$D$66,'가정'!$D$68,'가정'!$D$70))*('가정'!$D$9)/'가정'!$D$63*(CHOOSE('가정'!$D$7,'가정'!$D$65,'가정'!$D$67,'가정'!$D$69,'가정'!$D$71))*'가정'!$D$49*(1)*'가정'!$D$46-('가정'!$D$72+'가정'!$D$73+'가정'!$D$74)),"회수 불가") | C25: =IF(('가정'!$D$12*($A25)*('가정'!$D$15)*('가정'!$D$16)*('가정'!$D$9)*(INDEX('계산'!$C$13:$E$13,C$23))-((1)*'계산'!$C$18+'계산'!$C$22)*('가정'!$D$60)*'가정'!$D$46-'가정'!$D$50*(CHOOSE('가정'!$D$7,'가정'!$D$64,'가정'!$D$66,'가정'!$D$68,'가정'!$D$70))*('가정'!$D$9)/'가정'!$D$63*(CHOOSE('가정'!$D$7,'가정'!$D$65,'가정'!$D$67,'가정'!$D$69,'가정'!$D$71))*'가정'!$D$49*(1)*'가정'!$D$46-('가정'!$D$72+'가정'!$D$73+'가정'!$D$74))>0,(((1)*('계산'!$C$18+'계산'!$C$19)+'계산'!$C$22)*(1+('가정'!$D$57))*'가정'!$D$46+'가정'!$D$58)/('가정'!$D$12*($A25)*('가정'!$D$15)*('가정'!$D$16)*('가정'!$D$9)*(INDEX('계산'!$C$13:$E$13,C$23))-((1)*'계산'!$C$18+'계산'!$C$22)*('가정'!$D$60)*'가정'!$D$46-'가정'!$D$50*(CHOOSE('가정'!$D$7,'가정'!$D$64,'가정'!$D$66,'가정'!$D$68,'가정'!$D$70))*('가정'!$D$9)/'가정'!$D$63*(CHOOSE('가정'!$D$7,'가정'!$D$65,'가정'!$D$67,'가정'!$D$69,'가정'!$D$71))*'가정'!$D$49*(1)*'가정'!$D$46-('가정'!$D$72+'가정'!$D$73+'가정'!$D$74)),"회수 불가") | D25: =IF(('가정'!$D$12*($A25)*('가정'!$D$15)*('가정'!$D$16)*('가정'!$D$9)*(INDEX('계산'!$C$13:$E$13,D$23))-((1)*'계산'!$C$18+'계산'!$C$22)*('가정'!$D$60)*'가정'!$D$46-'가정'!$D$50*(CHOOSE('가정'!$D$7,'가정'!$D$64,'가정'!$D$66,'가정'!$D$68,'가정'!$D$70))*('가정'!$D$9)/'가정'!$D$63*(CHOOSE('가정'!$D$7,'가정'!$D$65,'가정'!$D$67,'가정'!$D$69,'가정'!$D$71))*'가정'!$D$49*(1)*'가정'!$D$46-('가정'!$D$72+'가정'!$D$73+'가정'!$D$74))>0,(((1)*('계산'!$C$18+'계산'!$C$19)+'계산'!$C$22)*(1+('가정'!$D$57))*'가정'!$D$46+'가정'!$D$58)/('가정'!$D$12*($A25)*('가정'!$D$15)*('가정'!$D$16)*('가정'!$D$9)*(INDEX('계산'!$C$13:$E$13,D$23))-((1)*'계산'!$C$18+'계산'!$C$22)*('가정'!$D$60)*'가정'!$D$46-'가정'!$D$50*(CHOOSE('가정'!$D$7,'가정'!$D$64,'가정'!$D$66,'가정'!$D$68,'가정'!$D$70))*('가정'!$D$9)/'가정'!$D$63*(CHOOSE('가정'!$D$7,'가정'!$D$65,'가정'!$D$67,'가정'!$D$69,'가정'!$D$71))*'가정'!$D$49*(1)*'가정'!$D$46-('가정'!$D$72+'가정'!$D$73+'가정'!$D$74)),"회수 불가")
A26: 0.75 | B26: =IF(('가정'!$D$12*($A26)*('가정'!$D$15)*('가정'!$D$16)*('가정'!$D$9)*(INDEX('계산'!$C$13:$E$13,B$23))-((1)*'계산'!$C$18+'계산'!$C$22)*('가정'!$D$60)*'가정'!$D$46-'가정'!$D$50*(CHOOSE('가정'!$D$7,'가정'!$D$64,'가정'!$D$66,'가정'!$D$68,'가정'!$D$70))*('가정'!$D$9)/'가정'!$D$63*(CHOOSE('가정'!$D$7,'가정'!$D$65,'가정'!$D$67,'가정'!$D$69,'가정'!$D$71))*'가정'!$D$49*(1)*'가정'!$D$46-('가정'!$D$72+'가정'!$D$73+'가정'!$D$74))>0,(((1)*('계산'!$C$18+'계산'!$C$19)+'계산'!$C$22)*(1+('가정'!$D$57))*'가정'!$D$46+'가정'!$D$58)/('가정'!$D$12*($A26)*('가정'!$D$15)*('가정'!$D$16)*('가정'!$D$9)*(INDEX('계산'!$C$13:$E$13,B$23))-((1)*'계산'!$C$18+'계산'!$C$22)*('가정'!$D$60)*'가정'!$D$46-'가정'!$D$50*(CHOOSE('가정'!$D$7,'가정'!$D$64,'가정'!$D$66,'가정'!$D$68,'가정'!$D$70))*('가정'!$D$9)/'가정'!$D$63*(CHOOSE('가정'!$D$7,'가정'!$D$65,'가정'!$D$67,'가정'!$D$69,'가정'!$D$71))*'가정'!$D$49*(1)*'가정'!$D$46-('가정'!$D$72+'가정'!$D$73+'가정'!$D$74)),"회수 불가") | C26: =IF(('가정'!$D$12*($A26)*('가정'!$D$15)*('가정'!$D$16)*('가정'!$D$9)*(INDEX('계산'!$C$13:$E$13,C$23))-((1)*'계산'!$C$18+'계산'!$C$22)*('가정'!$D$60)*'가정'!$D$46-'가정'!$D$50*(CHOOSE('가정'!$D$7,'가정'!$D$64,'가정'!$D$66,'가정'!$D$68,'가정'!$D$70))*('가정'!$D$9)/'가정'!$D$63*(CHOOSE('가정'!$D$7,'가정'!$D$65,'가정'!$D$67,'가정'!$D$69,'가정'!$D$71))*'가정'!$D$49*(1)*'가정'!$D$46-('가정'!$D$72+'가정'!$D$73+'가정'!$D$74))>0,(((1)*('계산'!$C$18+'계산'!$C$19)+'계산'!$C$22)*(1+('가정'!$D$57))*'가정'!$D$46+'가정'!$D$58)/('가정'!$D$12*($A26)*('가정'!$D$15)*('가정'!$D$16)*('가정'!$D$9)*(INDEX('계산'!$C$13:$E$13,C$23))-((1)*'계산'!$C$18+'계산'!$C$22)*('가정'!$D$60)*'가정'!$D$46-'가정'!$D$50*(CHOOSE('가정'!$D$7,'가정'!$D$64,'가정'!$D$66,'가정'!$D$68,'가정'!$D$70))*('가정'!$D$9)/'가정'!$D$63*(CHOOSE('가정'!$D$7,'가정'!$D$65,'가정'!$D$67,'가정'!$D$69,'가정'!$D$71))*'가정'!$D$49*(1)*'가정'!$D$46-('가정'!$D$72+'가정'!$D$73+'가정'!$D$74)),"회수 불가") | D26: =IF(('가정'!$D$12*($A26)*('가정'!$D$15)*('가정'!$D$16)*('가정'!$D$9)*(INDEX('계산'!$C$13:$E$13,D$23))-((1)*'계산'!$C$18+'계산'!$C$22)*('가정'!$D$60)*'가정'!$D$46-'가정'!$D$50*(CHOOSE('가정'!$D$7,'가정'!$D$64,'가정'!$D$66,'가정'!$D$68,'가정'!$D$70))*('가정'!$D$9)/'가정'!$D$63*(CHOOSE('가정'!$D$7,'가정'!$D$65,'가정'!$D$67,'가정'!$D$69,'가정'!$D$71))*'가정'!$D$49*(1)*'가정'!$D$46-('가정'!$D$72+'가정'!$D$73+'가정'!$D$74))>0,(((1)*('계산'!$C$18+'계산'!$C$19)+'계산'!$C$22)*(1+('가정'!$D$57))*'가정'!$D$46+'가정'!$D$58)/('가정'!$D$12*($A26)*('가정'!$D$15)*('가정'!$D$16)*('가정'!$D$9)*(INDEX('계산'!$C$13:$E$13,D$23))-((1)*'계산'!$C$18+'계산'!$C$22)*('가정'!$D$60)*'가정'!$D$46-'가정'!$D$50*(CHOOSE('가정'!$D$7,'가정'!$D$64,'가정'!$D$66,'가정'!$D$68,'가정'!$D$70))*('가정'!$D$9)/'가정'!$D$63*(CHOOSE('가정'!$D$7,'가정'!$D$65,'가정'!$D$67,'가정'!$D$69,'가정'!$D$71))*'가정'!$D$49*(1)*'가정'!$D$46-('가정'!$D$72+'가정'!$D$73+'가정'!$D$74)),"회수 불가")
A27: 1 | B27: =IF(('가정'!$D$12*($A27)*('가정'!$D$15)*('가정'!$D$16)*('가정'!$D$9)*(INDEX('계산'!$C$13:$E$13,B$23))-((1)*'계산'!$C$18+'계산'!$C$22)*('가정'!$D$60)*'가정'!$D$46-'가정'!$D$50*(CHOOSE('가정'!$D$7,'가정'!$D$64,'가정'!$D$66,'가정'!$D$68,'가정'!$D$70))*('가정'!$D$9)/'가정'!$D$63*(CHOOSE('가정'!$D$7,'가정'!$D$65,'가정'!$D$67,'가정'!$D$69,'가정'!$D$71))*'가정'!$D$49*(1)*'가정'!$D$46-('가정'!$D$72+'가정'!$D$73+'가정'!$D$74))>0,(((1)*('계산'!$C$18+'계산'!$C$19)+'계산'!$C$22)*(1+('가정'!$D$57))*'가정'!$D$46+'가정'!$D$58)/('가정'!$D$12*($A27)*('가정'!$D$15)*('가정'!$D$16)*('가정'!$D$9)*(INDEX('계산'!$C$13:$E$13,B$23))-((1)*'계산'!$C$18+'계산'!$C$22)*('가정'!$D$60)*'가정'!$D$46-'가정'!$D$50*(CHOOSE('가정'!$D$7,'가정'!$D$64,'가정'!$D$66,'가정'!$D$68,'가정'!$D$70))*('가정'!$D$9)/'가정'!$D$63*(CHOOSE('가정'!$D$7,'가정'!$D$65,'가정'!$D$67,'가정'!$D$69,'가정'!$D$71))*'가정'!$D$49*(1)*'가정'!$D$46-('가정'!$D$72+'가정'!$D$73+'가정'!$D$74)),"회수 불가") | C27: =IF(('가정'!$D$12*($A27)*('가정'!$D$15)*('가정'!$D$16)*('가정'!$D$9)*(INDEX('계산'!$C$13:$E$13,C$23))-((1)*'계산'!$C$18+'계산'!$C$22)*('가정'!$D$60)*'가정'!$D$46-'가정'!$D$50*(CHOOSE('가정'!$D$7,'가정'!$D$64,'가정'!$D$66,'가정'!$D$68,'가정'!$D$70))*('가정'!$D$9)/'가정'!$D$63*(CHOOSE('가정'!$D$7,'가정'!$D$65,'가정'!$D$67,'가정'!$D$69,'가정'!$D$71))*'가정'!$D$49*(1)*'가정'!$D$46-('가정'!$D$72+'가정'!$D$73+'가정'!$D$74))>0,(((1)*('계산'!$C$18+'계산'!$C$19)+'계산'!$C$22)*(1+('가정'!$D$57))*'가정'!$D$46+'가정'!$D$58)/('가정'!$D$12*($A27)*('가정'!$D$15)*('가정'!$D$16)*('가정'!$D$9)*(INDEX('계산'!$C$13:$E$13,C$23))-((1)*'계산'!$C$18+'계산'!$C$22)*('가정'!$D$60)*'가정'!$D$46-'가정'!$D$50*(CHOOSE('가정'!$D$7,'가정'!$D$64,'가정'!$D$66,'가정'!$D$68,'가정'!$D$70))*('가정'!$D$9)/'가정'!$D$63*(CHOOSE('가정'!$D$7,'가정'!$D$65,'가정'!$D$67,'가정'!$D$69,'가정'!$D$71))*'가정'!$D$49*(1)*'가정'!$D$46-('가정'!$D$72+'가정'!$D$73+'가정'!$D$74)),"회수 불가") | D27: =IF(('가정'!$D$12*($A27)*('가정'!$D$15)*('가정'!$D$16)*('가정'!$D$9)*(INDEX('계산'!$C$13:$E$13,D$23))-((1)*'계산'!$C$18+'계산'!$C$22)*('가정'!$D$60)*'가정'!$D$46-'가정'!$D$50*(CHOOSE('가정'!$D$7,'가정'!$D$64,'가정'!$D$66,'가정'!$D$68,'가정'!$D$70))*('가정'!$D$9)/'가정'!$D$63*(CHOOSE('가정'!$D$7,'가정'!$D$65,'가정'!$D$67,'가정'!$D$69,'가정'!$D$71))*'가정'!$D$49*(1)*'가정'!$D$46-('가정'!$D$72+'가정'!$D$73+'가정'!$D$74))>0,(((1)*('계산'!$C$18+'계산'!$C$19)+'계산'!$C$22)*(1+('가정'!$D$57))*'가정'!$D$46+'가정'!$D$58)/('가정'!$D$12*($A27)*('가정'!$D$15)*('가정'!$D$16)*('가정'!$D$9)*(INDEX('계산'!$C$13:$E$13,D$23))-((1)*'계산'!$C$18+'계산'!$C$22)*('가정'!$D$60)*'가정'!$D$46-'가정'!$D$50*(CHOOSE('가정'!$D$7,'가정'!$D$64,'가정'!$D$66,'가정'!$D$68,'가정'!$D$70))*('가정'!$D$9)/'가정'!$D$63*(CHOOSE('가정'!$D$7,'가정'!$D$65,'가정'!$D$67,'가정'!$D$69,'가정'!$D$71))*'가정'!$D$49*(1)*'가정'!$D$46-('가정'!$D$72+'가정'!$D$73+'가정'!$D$74)),"회수 불가")
A28: 1.25 | B28: =IF(('가정'!$D$12*($A28)*('가정'!$D$15)*('가정'!$D$16)*('가정'!$D$9)*(INDEX('계산'!$C$13:$E$13,B$23))-((1)*'계산'!$C$18+'계산'!$C$22)*('가정'!$D$60)*'가정'!$D$46-'가정'!$D$50*(CHOOSE('가정'!$D$7,'가정'!$D$64,'가정'!$D$66,'가정'!$D$68,'가정'!$D$70))*('가정'!$D$9)/'가정'!$D$63*(CHOOSE('가정'!$D$7,'가정'!$D$65,'가정'!$D$67,'가정'!$D$69,'가정'!$D$71))*'가정'!$D$49*(1)*'가정'!$D$46-('가정'!$D$72+'가정'!$D$73+'가정'!$D$74))>0,(((1)*('계산'!$C$18+'계산'!$C$19)+'계산'!$C$22)*(1+('가정'!$D$57))*'가정'!$D$46+'가정'!$D$58)/('가정'!$D$12*($A28)*('가정'!$D$15)*('가정'!$D$16)*('가정'!$D$9)*(INDEX('계산'!$C$13:$E$13,B$23))-((1)*'계산'!$C$18+'계산'!$C$22)*('가정'!$D$60)*'가정'!$D$46-'가정'!$D$50*(CHOOSE('가정'!$D$7,'가정'!$D$64,'가정'!$D$66,'가정'!$D$68,'가정'!$D$70))*('가정'!$D$9)/'가정'!$D$63*(CHOOSE('가정'!$D$7,'가정'!$D$65,'가정'!$D$67,'가정'!$D$69,'가정'!$D$71))*'가정'!$D$49*(1)*'가정'!$D$46-('가정'!$D$72+'가정'!$D$73+'가정'!$D$74)),"회수 불가") | C28: =IF(('가정'!$D$12*($A28)*('가정'!$D$15)*('가정'!$D$16)*('가정'!$D$9)*(INDEX('계산'!$C$13:$E$13,C$23))-((1)*'계산'!$C$18+'계산'!$C$22)*('가정'!$D$60)*'가정'!$D$46-'가정'!$D$50*(CHOOSE('가정'!$D$7,'가정'!$D$64,'가정'!$D$66,'가정'!$D$68,'가정'!$D$70))*('가정'!$D$9)/'가정'!$D$63*(CHOOSE('가정'!$D$7,'가정'!$D$65,'가정'!$D$67,'가정'!$D$69,'가정'!$D$71))*'가정'!$D$49*(1)*'가정'!$D$46-('가정'!$D$72+'가정'!$D$73+'가정'!$D$74))>0,(((1)*('계산'!$C$18+'계산'!$C$19)+'계산'!$C$22)*(1+('가정'!$D$57))*'가정'!$D$46+'가정'!$D$58)/('가정'!$D$12*($A28)*('가정'!$D$15)*('가정'!$D$16)*('가정'!$D$9)*(INDEX('계산'!$C$13:$E$13,C$23))-((1)*'계산'!$C$18+'계산'!$C$22)*('가정'!$D$60)*'가정'!$D$46-'가정'!$D$50*(CHOOSE('가정'!$D$7,'가정'!$D$64,'가정'!$D$66,'가정'!$D$68,'가정'!$D$70))*('가정'!$D$9)/'가정'!$D$63*(CHOOSE('가정'!$D$7,'가정'!$D$65,'가정'!$D$67,'가정'!$D$69,'가정'!$D$71))*'가정'!$D$49*(1)*'가정'!$D$46-('가정'!$D$72+'가정'!$D$73+'가정'!$D$74)),"회수 불가") | D28: =IF(('가정'!$D$12*($A28)*('가정'!$D$15)*('가정'!$D$16)*('가정'!$D$9)*(INDEX('계산'!$C$13:$E$13,D$23))-((1)*'계산'!$C$18+'계산'!$C$22)*('가정'!$D$60)*'가정'!$D$46-'가정'!$D$50*(CHOOSE('가정'!$D$7,'가정'!$D$64,'가정'!$D$66,'가정'!$D$68,'가정'!$D$70))*('가정'!$D$9)/'가정'!$D$63*(CHOOSE('가정'!$D$7,'가정'!$D$65,'가정'!$D$67,'가정'!$D$69,'가정'!$D$71))*'가정'!$D$49*(1)*'가정'!$D$46-('가정'!$D$72+'가정'!$D$73+'가정'!$D$74))>0,(((1)*('계산'!$C$18+'계산'!$C$19)+'계산'!$C$22)*(1+('가정'!$D$57))*'가정'!$D$46+'가정'!$D$58)/('가정'!$D$12*($A28)*('가정'!$D$15)*('가정'!$D$16)*('가정'!$D$9)*(INDEX('계산'!$C$13:$E$13,D$23))-((1)*'계산'!$C$18+'계산'!$C$22)*('가정'!$D$60)*'가정'!$D$46-'가정'!$D$50*(CHOOSE('가정'!$D$7,'가정'!$D$64,'가정'!$D$66,'가정'!$D$68,'가정'!$D$70))*('가정'!$D$9)/'가정'!$D$63*(CHOOSE('가정'!$D$7,'가정'!$D$65,'가정'!$D$67,'가정'!$D$69,'가정'!$D$71))*'가정'!$D$49*(1)*'가정'!$D$46-('가정'!$D$72+'가정'!$D$73+'가정'!$D$74)),"회수 불가")
A31: 2b. 속도비 x 인건비 시나리오 - 5년 NPV (백만 원)
A32: 속도비 \ 인건비 시나리오 | B32: 1 | C32: 2 | D32: 3
A33: 0.25 | B33: =((((1)*('계산'!$C$18+'계산'!$C$19)+'계산'!$C$22)*(1+('가정'!$D$57))*'가정'!$D$46+'가정'!$D$58)*-1+PV('가정'!$D$83,'가정'!$D$84,-('가정'!$D$12*($A33)*('가정'!$D$15)*('가정'!$D$16)*('가정'!$D$9)*(INDEX('계산'!$C$13:$E$13,B$32))-((1)*'계산'!$C$18+'계산'!$C$22)*('가정'!$D$60)*'가정'!$D$46-'가정'!$D$50*(CHOOSE('가정'!$D$7,'가정'!$D$64,'가정'!$D$66,'가정'!$D$68,'가정'!$D$70))*('가정'!$D$9)/'가정'!$D$63*(CHOOSE('가정'!$D$7,'가정'!$D$65,'가정'!$D$67,'가정'!$D$69,'가정'!$D$71))*'가정'!$D$49*(1)*'가정'!$D$46-('가정'!$D$72+'가정'!$D$73+'가정'!$D$74))))/1000000 | C33: =((((1)*('계산'!$C$18+'계산'!$C$19)+'계산'!$C$22)*(1+('가정'!$D$57))*'가정'!$D$46+'가정'!$D$58)*-1+PV('가정'!$D$83,'가정'!$D$84,-('가정'!$D$12*($A33)*('가정'!$D$15)*('가정'!$D$16)*('가정'!$D$9)*(INDEX('계산'!$C$13:$E$13,C$32))-((1)*'계산'!$C$18+'계산'!$C$22)*('가정'!$D$60)*'가정'!$D$46-'가정'!$D$50*(CHOOSE('가정'!$D$7,'가정'!$D$64,'가정'!$D$66,'가정'!$D$68,'가정'!$D$70))*('가정'!$D$9)/'가정'!$D$63*(CHOOSE('가정'!$D$7,'가정'!$D$65,'가정'!$D$67,'가정'!$D$69,'가정'!$D$71))*'가정'!$D$49*(1)*'가정'!$D$46-('가정'!$D$72+'가정'!$D$73+'가정'!$D$74))))/1000000 | D33: =((((1)*('계산'!$C$18+'계산'!$C$19)+'계산'!$C$22)*(1+('가정'!$D$57))*'가정'!$D$46+'가정'!$D$58)*-1+PV('가정'!$D$83,'가정'!$D$84,-('가정'!$D$12*($A33)*('가정'!$D$15)*('가정'!$D$16)*('가정'!$D$9)*(INDEX('계산'!$C$13:$E$13,D$32))-((1)*'계산'!$C$18+'계산'!$C$22)*('가정'!$D$60)*'가정'!$D$46-'가정'!$D$50*(CHOOSE('가정'!$D$7,'가정'!$D$64,'가정'!$D$66,'가정'!$D$68,'가정'!$D$70))*('가정'!$D$9)/'가정'!$D$63*(CHOOSE('가정'!$D$7,'가정'!$D$65,'가정'!$D$67,'가정'!$D$69,'가정'!$D$71))*'가정'!$D$49*(1)*'가정'!$D$46-('가정'!$D$72+'가정'!$D$73+'가정'!$D$74))))/1000000
A34: 0.5 | B34: =((((1)*('계산'!$C$18+'계산'!$C$19)+'계산'!$C$22)*(1+('가정'!$D$57))*'가정'!$D$46+'가정'!$D$58)*-1+PV('가정'!$D$83,'가정'!$D$84,-('가정'!$D$12*($A34)*('가정'!$D$15)*('가정'!$D$16)*('가정'!$D$9)*(INDEX('계산'!$C$13:$E$13,B$32))-((1)*'계산'!$C$18+'계산'!$C$22)*('가정'!$D$60)*'가정'!$D$46-'가정'!$D$50*(CHOOSE('가정'!$D$7,'가정'!$D$64,'가정'!$D$66,'가정'!$D$68,'가정'!$D$70))*('가정'!$D$9)/'가정'!$D$63*(CHOOSE('가정'!$D$7,'가정'!$D$65,'가정'!$D$67,'가정'!$D$69,'가정'!$D$71))*'가정'!$D$49*(1)*'가정'!$D$46-('가정'!$D$72+'가정'!$D$73+'가정'!$D$74))))/1000000 | C34: =((((1)*('계산'!$C$18+'계산'!$C$19)+'계산'!$C$22)*(1+('가정'!$D$57))*'가정'!$D$46+'가정'!$D$58)*-1+PV('가정'!$D$83,'가정'!$D$84,-('가정'!$D$12*($A34)*('가정'!$D$15)*('가정'!$D$16)*('가정'!$D$9)*(INDEX('계산'!$C$13:$E$13,C$32))-((1)*'계산'!$C$18+'계산'!$C$22)*('가정'!$D$60)*'가정'!$D$46-'가정'!$D$50*(CHOOSE('가정'!$D$7,'가정'!$D$64,'가정'!$D$66,'가정'!$D$68,'가정'!$D$70))*('가정'!$D$9)/'가정'!$D$63*(CHOOSE('가정'!$D$7,'가정'!$D$65,'가정'!$D$67,'가정'!$D$69,'가정'!$D$71))*'가정'!$D$49*(1)*'가정'!$D$46-('가정'!$D$72+'가정'!$D$73+'가정'!$D$74))))/1000000 | D34: =((((1)*('계산'!$C$18+'계산'!$C$19)+'계산'!$C$22)*(1+('가정'!$D$57))*'가정'!$D$46+'가정'!$D$58)*-1+PV('가정'!$D$83,'가정'!$D$84,-('가정'!$D$12*($A34)*('가정'!$D$15)*('가정'!$D$16)*('가정'!$D$9)*(INDEX('계산'!$C$13:$E$13,D$32))-((1)*'계산'!$C$18+'계산'!$C$22)*('가정'!$D$60)*'가정'!$D$46-'가정'!$D$50*(CHOOSE('가정'!$D$7,'가정'!$D$64,'가정'!$D$66,'가정'!$D$68,'가정'!$D$70))*('가정'!$D$9)/'가정'!$D$63*(CHOOSE('가정'!$D$7,'가정'!$D$65,'가정'!$D$67,'가정'!$D$69,'가정'!$D$71))*'가정'!$D$49*(1)*'가정'!$D$46-('가정'!$D$72+'가정'!$D$73+'가정'!$D$74))))/1000000
A35: 0.75 | B35: =((((1)*('계산'!$C$18+'계산'!$C$19)+'계산'!$C$22)*(1+('가정'!$D$57))*'가정'!$D$46+'가정'!$D$58)*-1+PV('가정'!$D$83,'가정'!$D$84,-('가정'!$D$12*($A35)*('가정'!$D$15)*('가정'!$D$16)*('가정'!$D$9)*(INDEX('계산'!$C$13:$E$13,B$32))-((1)*'계산'!$C$18+'계산'!$C$22)*('가정'!$D$60)*'가정'!$D$46-'가정'!$D$50*(CHOOSE('가정'!$D$7,'가정'!$D$64,'가정'!$D$66,'가정'!$D$68,'가정'!$D$70))*('가정'!$D$9)/'가정'!$D$63*(CHOOSE('가정'!$D$7,'가정'!$D$65,'가정'!$D$67,'가정'!$D$69,'가정'!$D$71))*'가정'!$D$49*(1)*'가정'!$D$46-('가정'!$D$72+'가정'!$D$73+'가정'!$D$74))))/1000000 | C35: =((((1)*('계산'!$C$18+'계산'!$C$19)+'계산'!$C$22)*(1+('가정'!$D$57))*'가정'!$D$46+'가정'!$D$58)*-1+PV('가정'!$D$83,'가정'!$D$84,-('가정'!$D$12*($A35)*('가정'!$D$15)*('가정'!$D$16)*('가정'!$D$9)*(INDEX('계산'!$C$13:$E$13,C$32))-((1)*'계산'!$C$18+'계산'!$C$22)*('가정'!$D$60)*'가정'!$D$46-'가정'!$D$50*(CHOOSE('가정'!$D$7,'가정'!$D$64,'가정'!$D$66,'가정'!$D$68,'가정'!$D$70))*('가정'!$D$9)/'가정'!$D$63*(CHOOSE('가정'!$D$7,'가정'!$D$65,'가정'!$D$67,'가정'!$D$69,'가정'!$D$71))*'가정'!$D$49*(1)*'가정'!$D$46-('가정'!$D$72+'가정'!$D$73+'가정'!$D$74))))/1000000 | D35: =((((1)*('계산'!$C$18+'계산'!$C$19)+'계산'!$C$22)*(1+('가정'!$D$57))*'가정'!$D$46+'가정'!$D$58)*-1+PV('가정'!$D$83,'가정'!$D$84,-('가정'!$D$12*($A35)*('가정'!$D$15)*('가정'!$D$16)*('가정'!$D$9)*(INDEX('계산'!$C$13:$E$13,D$32))-((1)*'계산'!$C$18+'계산'!$C$22)*('가정'!$D$60)*'가정'!$D$46-'가정'!$D$50*(CHOOSE('가정'!$D$7,'가정'!$D$64,'가정'!$D$66,'가정'!$D$68,'가정'!$D$70))*('가정'!$D$9)/'가정'!$D$63*(CHOOSE('가정'!$D$7,'가정'!$D$65,'가정'!$D$67,'가정'!$D$69,'가정'!$D$71))*'가정'!$D$49*(1)*'가정'!$D$46-('가정'!$D$72+'가정'!$D$73+'가정'!$D$74))))/1000000
A36: 1 | B36: =((((1)*('계산'!$C$18+'계산'!$C$19)+'계산'!$C$22)*(1+('가정'!$D$57))*'가정'!$D$46+'가정'!$D$58)*-1+PV('가정'!$D$83,'가정'!$D$84,-('가정'!$D$12*($A36)*('가정'!$D$15)*('가정'!$D$16)*('가정'!$D$9)*(INDEX('계산'!$C$13:$E$13,B$32))-((1)*'계산'!$C$18+'계산'!$C$22)*('가정'!$D$60)*'가정'!$D$46-'가정'!$D$50*(CHOOSE('가정'!$D$7,'가정'!$D$64,'가정'!$D$66,'가정'!$D$68,'가정'!$D$70))*('가정'!$D$9)/'가정'!$D$63*(CHOOSE('가정'!$D$7,'가정'!$D$65,'가정'!$D$67,'가정'!$D$69,'가정'!$D$71))*'가정'!$D$49*(1)*'가정'!$D$46-('가정'!$D$72+'가정'!$D$73+'가정'!$D$74))))/1000000 | C36: =((((1)*('계산'!$C$18+'계산'!$C$19)+'계산'!$C$22)*(1+('가정'!$D$57))*'가정'!$D$46+'가정'!$D$58)*-1+PV('가정'!$D$83,'가정'!$D$84,-('가정'!$D$12*($A36)*('가정'!$D$15)*('가정'!$D$16)*('가정'!$D$9)*(INDEX('계산'!$C$13:$E$13,C$32))-((1)*'계산'!$C$18+'계산'!$C$22)*('가정'!$D$60)*'가정'!$D$46-'가정'!$D$50*(CHOOSE('가정'!$D$7,'가정'!$D$64,'가정'!$D$66,'가정'!$D$68,'가정'!$D$70))*('가정'!$D$9)/'가정'!$D$63*(CHOOSE('가정'!$D$7,'가정'!$D$65,'가정'!$D$67,'가정'!$D$69,'가정'!$D$71))*'가정'!$D$49*(1)*'가정'!$D$46-('가정'!$D$72+'가정'!$D$73+'가정'!$D$74))))/1000000 | D36: =((((1)*('계산'!$C$18+'계산'!$C$19)+'계산'!$C$22)*(1+('가정'!$D$57))*'가정'!$D$46+'가정'!$D$58)*-1+PV('가정'!$D$83,'가정'!$D$84,-('가정'!$D$12*($A36)*('가정'!$D$15)*('가정'!$D$16)*('가정'!$D$9)*(INDEX('계산'!$C$13:$E$13,D$32))-((1)*'계산'!$C$18+'계산'!$C$22)*('가정'!$D$60)*'가정'!$D$46-'가정'!$D$50*(CHOOSE('가정'!$D$7,'가정'!$D$64,'가정'!$D$66,'가정'!$D$68,'가정'!$D$70))*('가정'!$D$9)/'가정'!$D$63*(CHOOSE('가정'!$D$7,'가정'!$D$65,'가정'!$D$67,'가정'!$D$69,'가정'!$D$71))*'가정'!$D$49*(1)*'가정'!$D$46-('가정'!$D$72+'가정'!$D$73+'가정'!$D$74))))/1000000
A37: 1.25 | B37: =((((1)*('계산'!$C$18+'계산'!$C$19)+'계산'!$C$22)*(1+('가정'!$D$57))*'가정'!$D$46+'가정'!$D$58)*-1+PV('가정'!$D$83,'가정'!$D$84,-('가정'!$D$12*($A37)*('가정'!$D$15)*('가정'!$D$16)*('가정'!$D$9)*(INDEX('계산'!$C$13:$E$13,B$32))-((1)*'계산'!$C$18+'계산'!$C$22)*('가정'!$D$60)*'가정'!$D$46-'가정'!$D$50*(CHOOSE('가정'!$D$7,'가정'!$D$64,'가정'!$D$66,'가정'!$D$68,'가정'!$D$70))*('가정'!$D$9)/'가정'!$D$63*(CHOOSE('가정'!$D$7,'가정'!$D$65,'가정'!$D$67,'가정'!$D$69,'가정'!$D$71))*'가정'!$D$49*(1)*'가정'!$D$46-('가정'!$D$72+'가정'!$D$73+'가정'!$D$74))))/1000000 | C37: =((((1)*('계산'!$C$18+'계산'!$C$19)+'계산'!$C$22)*(1+('가정'!$D$57))*'가정'!$D$46+'가정'!$D$58)*-1+PV('가정'!$D$83,'가정'!$D$84,-('가정'!$D$12*($A37)*('가정'!$D$15)*('가정'!$D$16)*('가정'!$D$9)*(INDEX('계산'!$C$13:$E$13,C$32))-((1)*'계산'!$C$18+'계산'!$C$22)*('가정'!$D$60)*'가정'!$D$46-'가정'!$D$50*(CHOOSE('가정'!$D$7,'가정'!$D$64,'가정'!$D$66,'가정'!$D$68,'가정'!$D$70))*('가정'!$D$9)/'가정'!$D$63*(CHOOSE('가정'!$D$7,'가정'!$D$65,'가정'!$D$67,'가정'!$D$69,'가정'!$D$71))*'가정'!$D$49*(1)*'가정'!$D$46-('가정'!$D$72+'가정'!$D$73+'가정'!$D$74))))/1000000 | D37: =((((1)*('계산'!$C$18+'계산'!$C$19)+'계산'!$C$22)*(1+('가정'!$D$57))*'가정'!$D$46+'가정'!$D$58)*-1+PV('가정'!$D$83,'가정'!$D$84,-('가정'!$D$12*($A37)*('가정'!$D$15)*('가정'!$D$16)*('가정'!$D$9)*(INDEX('계산'!$C$13:$E$13,D$32))-((1)*'계산'!$C$18+'계산'!$C$22)*('가정'!$D$60)*'가정'!$D$46-'가정'!$D$50*(CHOOSE('가정'!$D$7,'가정'!$D$64,'가정'!$D$66,'가정'!$D$68,'가정'!$D$70))*('가정'!$D$9)/'가정'!$D$63*(CHOOSE('가정'!$D$7,'가정'!$D$65,'가정'!$D$67,'가정'!$D$69,'가정'!$D$71))*'가정'!$D$49*(1)*'가정'!$D$46-('가정'!$D$72+'가정'!$D$73+'가정'!$D$74))))/1000000
A40: 3a. 손 교체 f x 교체당 비용 비율 - 회수 기간 (년), 2교대
A41: N(셀 합계 연 교체 횟수) = 손 개수 x f. 인건비·속도비는 선택 시나리오. Q7 표 6-2a와 같은 틀(Q7은 구 인건비 4,700만 원 기준이라 값이 다름. 구 가정 재현은 검산 시트).
A42: f (손 1개당 연 교체) \ 교체당 비용 비율 | B42: 0.1 | C42: 0.2 | D42: 0.3 | E42: 1
A43: 0 | B43: =IF(('가정'!$D$12*('가정'!$D$14)*('가정'!$D$15)*('가정'!$D$16)*(2)*('계산'!$C$14)-((1)*'계산'!$C$18+'계산'!$C$22)*('가정'!$D$60)*'가정'!$D$46-'가정'!$D$50*($A43)*(2)/'가정'!$D$63*(B$42)*'가정'!$D$49*(1)*'가정'!$D$46-('가정'!$D$72+'가정'!$D$73+'가정'!$D$74))>0,(((1)*('계산'!$C$18+'계산'!$C$19)+'계산'!$C$22)*(1+('가정'!$D$57))*'가정'!$D$46+'가정'!$D$58)/('가정'!$D$12*('가정'!$D$14)*('가정'!$D$15)*('가정'!$D$16)*(2)*('계산'!$C$14)-((1)*'계산'!$C$18+'계산'!$C$22)*('가정'!$D$60)*'가정'!$D$46-'가정'!$D$50*($A43)*(2)/'가정'!$D$63*(B$42)*'가정'!$D$49*(1)*'가정'!$D$46-('가정'!$D$72+'가정'!$D$73+'가정'!$D$74)),"회수 불가") | C43: =IF(('가정'!$D$12*('가정'!$D$14)*('가정'!$D$15)*('가정'!$D$16)*(2)*('계산'!$C$14)-((1)*'계산'!$C$18+'계산'!$C$22)*('가정'!$D$60)*'가정'!$D$46-'가정'!$D$50*($A43)*(2)/'가정'!$D$63*(C$42)*'가정'!$D$49*(1)*'가정'!$D$46-('가정'!$D$72+'가정'!$D$73+'가정'!$D$74))>0,(((1)*('계산'!$C$18+'계산'!$C$19)+'계산'!$C$22)*(1+('가정'!$D$57))*'가정'!$D$46+'가정'!$D$58)/('가정'!$D$12*('가정'!$D$14)*('가정'!$D$15)*('가정'!$D$16)*(2)*('계산'!$C$14)-((1)*'계산'!$C$18+'계산'!$C$22)*('가정'!$D$60)*'가정'!$D$46-'가정'!$D$50*($A43)*(2)/'가정'!$D$63*(C$42)*'가정'!$D$49*(1)*'가정'!$D$46-('가정'!$D$72+'가정'!$D$73+'가정'!$D$74)),"회수 불가") | D43: =IF(('가정'!$D$12*('가정'!$D$14)*('가정'!$D$15)*('가정'!$D$16)*(2)*('계산'!$C$14)-((1)*'계산'!$C$18+'계산'!$C$22)*('가정'!$D$60)*'가정'!$D$46-'가정'!$D$50*($A43)*(2)/'가정'!$D$63*(D$42)*'가정'!$D$49*(1)*'가정'!$D$46-('가정'!$D$72+'가정'!$D$73+'가정'!$D$74))>0,(((1)*('계산'!$C$18+'계산'!$C$19)+'계산'!$C$22)*(1+('가정'!$D$57))*'가정'!$D$46+'가정'!$D$58)/('가정'!$D$12*('가정'!$D$14)*('가정'!$D$15)*('가정'!$D$16)*(2)*('계산'!$C$14)-((1)*'계산'!$C$18+'계산'!$C$22)*('가정'!$D$60)*'가정'!$D$46-'가정'!$D$50*($A43)*(2)/'가정'!$D$63*(D$42)*'가정'!$D$49*(1)*'가정'!$D$46-('가정'!$D$72+'가정'!$D$73+'가정'!$D$74)),"회수 불가") | E43: =IF(('가정'!$D$12*('가정'!$D$14)*('가정'!$D$15)*('가정'!$D$16)*(2)*('계산'!$C$14)-((1)*'계산'!$C$18+'계산'!$C$22)*('가정'!$D$60)*'가정'!$D$46-'가정'!$D$50*($A43)*(2)/'가정'!$D$63*(E$42)*'가정'!$D$49*(1)*'가정'!$D$46-('가정'!$D$72+'가정'!$D$73+'가정'!$D$74))>0,(((1)*('계산'!$C$18+'계산'!$C$19)+'계산'!$C$22)*(1+('가정'!$D$57))*'가정'!$D$46+'가정'!$D$58)/('가정'!$D$12*('가정'!$D$14)*('가정'!$D$15)*('가정'!$D$16)*(2)*('계산'!$C$14)-((1)*'계산'!$C$18+'계산'!$C$22)*('가정'!$D$60)*'가정'!$D$46-'가정'!$D$50*($A43)*(2)/'가정'!$D$63*(E$42)*'가정'!$D$49*(1)*'가정'!$D$46-('가정'!$D$72+'가정'!$D$73+'가정'!$D$74)),"회수 불가")
A44: 0.5 | B44: =IF(('가정'!$D$12*('가정'!$D$14)*('가정'!$D$15)*('가정'!$D$16)*(2)*('계산'!$C$14)-((1)*'계산'!$C$18+'계산'!$C$22)*('가정'!$D$60)*'가정'!$D$46-'가정'!$D$50*($A44)*(2)/'가정'!$D$63*(B$42)*'가정'!$D$49*(1)*'가정'!$D$46-('가정'!$D$72+'가정'!$D$73+'가정'!$D$74))>0,(((1)*('계산'!$C$18+'계산'!$C$19)+'계산'!$C$22)*(1+('가정'!$D$57))*'가정'!$D$46+'가정'!$D$58)/('가정'!$D$12*('가정'!$D$14)*('가정'!$D$15)*('가정'!$D$16)*(2)*('계산'!$C$14)-((1)*'계산'!$C$18+'계산'!$C$22)*('가정'!$D$60)*'가정'!$D$46-'가정'!$D$50*($A44)*(2)/'가정'!$D$63*(B$42)*'가정'!$D$49*(1)*'가정'!$D$46-('가정'!$D$72+'가정'!$D$73+'가정'!$D$74)),"회수 불가") | C44: =IF(('가정'!$D$12*('가정'!$D$14)*('가정'!$D$15)*('가정'!$D$16)*(2)*('계산'!$C$14)-((1)*'계산'!$C$18+'계산'!$C$22)*('가정'!$D$60)*'가정'!$D$46-'가정'!$D$50*($A44)*(2)/'가정'!$D$63*(C$42)*'가정'!$D$49*(1)*'가정'!$D$46-('가정'!$D$72+'가정'!$D$73+'가정'!$D$74))>0,(((1)*('계산'!$C$18+'계산'!$C$19)+'계산'!$C$22)*(1+('가정'!$D$57))*'가정'!$D$46+'가정'!$D$58)/('가정'!$D$12*('가정'!$D$14)*('가정'!$D$15)*('가정'!$D$16)*(2)*('계산'!$C$14)-((1)*'계산'!$C$18+'계산'!$C$22)*('가정'!$D$60)*'가정'!$D$46-'가정'!$D$50*($A44)*(2)/'가정'!$D$63*(C$42)*'가정'!$D$49*(1)*'가정'!$D$46-('가정'!$D$72+'가정'!$D$73+'가정'!$D$74)),"회수 불가") | D44: =IF(('가정'!$D$12*('가정'!$D$14)*('가정'!$D$15)*('가정'!$D$16)*(2)*('계산'!$C$14)-((1)*'계산'!$C$18+'계산'!$C$22)*('가정'!$D$60)*'가정'!$D$46-'가정'!$D$50*($A44)*(2)/'가정'!$D$63*(D$42)*'가정'!$D$49*(1)*'가정'!$D$46-('가정'!$D$72+'가정'!$D$73+'가정'!$D$74))>0,(((1)*('계산'!$C$18+'계산'!$C$19)+'계산'!$C$22)*(1+('가정'!$D$57))*'가정'!$D$46+'가정'!$D$58)/('가정'!$D$12*('가정'!$D$14)*('가정'!$D$15)*('가정'!$D$16)*(2)*('계산'!$C$14)-((1)*'계산'!$C$18+'계산'!$C$22)*('가정'!$D$60)*'가정'!$D$46-'가정'!$D$50*($A44)*(2)/'가정'!$D$63*(D$42)*'가정'!$D$49*(1)*'가정'!$D$46-('가정'!$D$72+'가정'!$D$73+'가정'!$D$74)),"회수 불가") | E44: =IF(('가정'!$D$12*('가정'!$D$14)*('가정'!$D$15)*('가정'!$D$16)*(2)*('계산'!$C$14)-((1)*'계산'!$C$18+'계산'!$C$22)*('가정'!$D$60)*'가정'!$D$46-'가정'!$D$50*($A44)*(2)/'가정'!$D$63*(E$42)*'가정'!$D$49*(1)*'가정'!$D$46-('가정'!$D$72+'가정'!$D$73+'가정'!$D$74))>0,(((1)*('계산'!$C$18+'계산'!$C$19)+'계산'!$C$22)*(1+('가정'!$D$57))*'가정'!$D$46+'가정'!$D$58)/('가정'!$D$12*('가정'!$D$14)*('가정'!$D$15)*('가정'!$D$16)*(2)*('계산'!$C$14)-((1)*'계산'!$C$18+'계산'!$C$22)*('가정'!$D$60)*'가정'!$D$46-'가정'!$D$50*($A44)*(2)/'가정'!$D$63*(E$42)*'가정'!$D$49*(1)*'가정'!$D$46-('가정'!$D$72+'가정'!$D$73+'가정'!$D$74)),"회수 불가")
A45: 1 | B45: =IF(('가정'!$D$12*('가정'!$D$14)*('가정'!$D$15)*('가정'!$D$16)*(2)*('계산'!$C$14)-((1)*'계산'!$C$18+'계산'!$C$22)*('가정'!$D$60)*'가정'!$D$46-'가정'!$D$50*($A45)*(2)/'가정'!$D$63*(B$42)*'가정'!$D$49*(1)*'가정'!$D$46-('가정'!$D$72+'가정'!$D$73+'가정'!$D$74))>0,(((1)*('계산'!$C$18+'계산'!$C$19)+'계산'!$C$22)*(1+('가정'!$D$57))*'가정'!$D$46+'가정'!$D$58)/('가정'!$D$12*('가정'!$D$14)*('가정'!$D$15)*('가정'!$D$16)*(2)*('계산'!$C$14)-((1)*'계산'!$C$18+'계산'!$C$22)*('가정'!$D$60)*'가정'!$D$46-'가정'!$D$50*($A45)*(2)/'가정'!$D$63*(B$42)*'가정'!$D$49*(1)*'가정'!$D$46-('가정'!$D$72+'가정'!$D$73+'가정'!$D$74)),"회수 불가") | C45: =IF(('가정'!$D$12*('가정'!$D$14)*('가정'!$D$15)*('가정'!$D$16)*(2)*('계산'!$C$14)-((1)*'계산'!$C$18+'계산'!$C$22)*('가정'!$D$60)*'가정'!$D$46-'가정'!$D$50*($A45)*(2)/'가정'!$D$63*(C$42)*'가정'!$D$49*(1)*'가정'!$D$46-('가정'!$D$72+'가정'!$D$73+'가정'!$D$74))>0,(((1)*('계산'!$C$18+'계산'!$C$19)+'계산'!$C$22)*(1+('가정'!$D$57))*'가정'!$D$46+'가정'!$D$58)/('가정'!$D$12*('가정'!$D$14)*('가정'!$D$15)*('가정'!$D$16)*(2)*('계산'!$C$14)-((1)*'계산'!$C$18+'계산'!$C$22)*('가정'!$D$60)*'가정'!$D$46-'가정'!$D$50*($A45)*(2)/'가정'!$D$63*(C$42)*'가정'!$D$49*(1)*'가정'!$D$46-('가정'!$D$72+'가정'!$D$73+'가정'!$D$74)),"회수 불가") | D45: =IF(('가정'!$D$12*('가정'!$D$14)*('가정'!$D$15)*('가정'!$D$16)*(2)*('계산'!$C$14)-((1)*'계산'!$C$18+'계산'!$C$22)*('가정'!$D$60)*'가정'!$D$46-'가정'!$D$50*($A45)*(2)/'가정'!$D$63*(D$42)*'가정'!$D$49*(1)*'가정'!$D$46-('가정'!$D$72+'가정'!$D$73+'가정'!$D$74))>0,(((1)*('계산'!$C$18+'계산'!$C$19)+'계산'!$C$22)*(1+('가정'!$D$57))*'가정'!$D$46+'가정'!$D$58)/('가정'!$D$12*('가정'!$D$14)*('가정'!$D$15)*('가정'!$D$16)*(2)*('계산'!$C$14)-((1)*'계산'!$C$18+'계산'!$C$22)*('가정'!$D$60)*'가정'!$D$46-'가정'!$D$50*($A45)*(2)/'가정'!$D$63*(D$42)*'가정'!$D$49*(1)*'가정'!$D$46-('가정'!$D$72+'가정'!$D$73+'가정'!$D$74)),"회수 불가") | E45: =IF(('가정'!$D$12*('가정'!$D$14)*('가정'!$D$15)*('가정'!$D$16)*(2)*('계산'!$C$14)-((1)*'계산'!$C$18+'계산'!$C$22)*('가정'!$D$60)*'가정'!$D$46-'가정'!$D$50*($A45)*(2)/'가정'!$D$63*(E$42)*'가정'!$D$49*(1)*'가정'!$D$46-('가정'!$D$72+'가정'!$D$73+'가정'!$D$74))>0,(((1)*('계산'!$C$18+'계산'!$C$19)+'계산'!$C$22)*(1+('가정'!$D$57))*'가정'!$D$46+'가정'!$D$58)/('가정'!$D$12*('가정'!$D$14)*('가정'!$D$15)*('가정'!$D$16)*(2)*('계산'!$C$14)-((1)*'계산'!$C$18+'계산'!$C$22)*('가정'!$D$60)*'가정'!$D$46-'가정'!$D$50*($A45)*(2)/'가정'!$D$63*(E$42)*'가정'!$D$49*(1)*'가정'!$D$46-('가정'!$D$72+'가정'!$D$73+'가정'!$D$74)),"회수 불가")
A46: 2 | B46: =IF(('가정'!$D$12*('가정'!$D$14)*('가정'!$D$15)*('가정'!$D$16)*(2)*('계산'!$C$14)-((1)*'계산'!$C$18+'계산'!$C$22)*('가정'!$D$60)*'가정'!$D$46-'가정'!$D$50*($A46)*(2)/'가정'!$D$63*(B$42)*'가정'!$D$49*(1)*'가정'!$D$46-('가정'!$D$72+'가정'!$D$73+'가정'!$D$74))>0,(((1)*('계산'!$C$18+'계산'!$C$19)+'계산'!$C$22)*(1+('가정'!$D$57))*'가정'!$D$46+'가정'!$D$58)/('가정'!$D$12*('가정'!$D$14)*('가정'!$D$15)*('가정'!$D$16)*(2)*('계산'!$C$14)-((1)*'계산'!$C$18+'계산'!$C$22)*('가정'!$D$60)*'가정'!$D$46-'가정'!$D$50*($A46)*(2)/'가정'!$D$63*(B$42)*'가정'!$D$49*(1)*'가정'!$D$46-('가정'!$D$72+'가정'!$D$73+'가정'!$D$74)),"회수 불가") | C46: =IF(('가정'!$D$12*('가정'!$D$14)*('가정'!$D$15)*('가정'!$D$16)*(2)*('계산'!$C$14)-((1)*'계산'!$C$18+'계산'!$C$22)*('가정'!$D$60)*'가정'!$D$46-'가정'!$D$50*($A46)*(2)/'가정'!$D$63*(C$42)*'가정'!$D$49*(1)*'가정'!$D$46-('가정'!$D$72+'가정'!$D$73+'가정'!$D$74))>0,(((1)*('계산'!$C$18+'계산'!$C$19)+'계산'!$C$22)*(1+('가정'!$D$57))*'가정'!$D$46+'가정'!$D$58)/('가정'!$D$12*('가정'!$D$14)*('가정'!$D$15)*('가정'!$D$16)*(2)*('계산'!$C$14)-((1)*'계산'!$C$18+'계산'!$C$22)*('가정'!$D$60)*'가정'!$D$46-'가정'!$D$50*($A46)*(2)/'가정'!$D$63*(C$42)*'가정'!$D$49*(1)*'가정'!$D$46-('가정'!$D$72+'가정'!$D$73+'가정'!$D$74)),"회수 불가") | D46: =IF(('가정'!$D$12*('가정'!$D$14)*('가정'!$D$15)*('가정'!$D$16)*(2)*('계산'!$C$14)-((1)*'계산'!$C$18+'계산'!$C$22)*('가정'!$D$60)*'가정'!$D$46-'가정'!$D$50*($A46)*(2)/'가정'!$D$63*(D$42)*'가정'!$D$49*(1)*'가정'!$D$46-('가정'!$D$72+'가정'!$D$73+'가정'!$D$74))>0,(((1)*('계산'!$C$18+'계산'!$C$19)+'계산'!$C$22)*(1+('가정'!$D$57))*'가정'!$D$46+'가정'!$D$58)/('가정'!$D$12*('가정'!$D$14)*('가정'!$D$15)*('가정'!$D$16)*(2)*('계산'!$C$14)-((1)*'계산'!$C$18+'계산'!$C$22)*('가정'!$D$60)*'가정'!$D$46-'가정'!$D$50*($A46)*(2)/'가정'!$D$63*(D$42)*'가정'!$D$49*(1)*'가정'!$D$46-('가정'!$D$72+'가정'!$D$73+'가정'!$D$74)),"회수 불가") | E46: =IF(('가정'!$D$12*('가정'!$D$14)*('가정'!$D$15)*('가정'!$D$16)*(2)*('계산'!$C$14)-((1)*'계산'!$C$18+'계산'!$C$22)*('가정'!$D$60)*'가정'!$D$46-'가정'!$D$50*($A46)*(2)/'가정'!$D$63*(E$42)*'가정'!$D$49*(1)*'가정'!$D$46-('가정'!$D$72+'가정'!$D$73+'가정'!$D$74))>0,(((1)*('계산'!$C$18+'계산'!$C$19)+'계산'!$C$22)*(1+('가정'!$D$57))*'가정'!$D$46+'가정'!$D$58)/('가정'!$D$12*('가정'!$D$14)*('가정'!$D$15)*('가정'!$D$16)*(2)*('계산'!$C$14)-((1)*'계산'!$C$18+'계산'!$C$22)*('가정'!$D$60)*'가정'!$D$46-'가정'!$D$50*($A46)*(2)/'가정'!$D$63*(E$42)*'가정'!$D$49*(1)*'가정'!$D$46-('가정'!$D$72+'가정'!$D$73+'가정'!$D$74)),"회수 불가")
A47: 3 | B47: =IF(('가정'!$D$12*('가정'!$D$14)*('가정'!$D$15)*('가정'!$D$16)*(2)*('계산'!$C$14)-((1)*'계산'!$C$18+'계산'!$C$22)*('가정'!$D$60)*'가정'!$D$46-'가정'!$D$50*($A47)*(2)/'가정'!$D$63*(B$42)*'가정'!$D$49*(1)*'가정'!$D$46-('가정'!$D$72+'가정'!$D$73+'가정'!$D$74))>0,(((1)*('계산'!$C$18+'계산'!$C$19)+'계산'!$C$22)*(1+('가정'!$D$57))*'가정'!$D$46+'가정'!$D$58)/('가정'!$D$12*('가정'!$D$14)*('가정'!$D$15)*('가정'!$D$16)*(2)*('계산'!$C$14)-((1)*'계산'!$C$18+'계산'!$C$22)*('가정'!$D$60)*'가정'!$D$46-'가정'!$D$50*($A47)*(2)/'가정'!$D$63*(B$42)*'가정'!$D$49*(1)*'가정'!$D$46-('가정'!$D$72+'가정'!$D$73+'가정'!$D$74)),"회수 불가") | C47: =IF(('가정'!$D$12*('가정'!$D$14)*('가정'!$D$15)*('가정'!$D$16)*(2)*('계산'!$C$14)-((1)*'계산'!$C$18+'계산'!$C$22)*('가정'!$D$60)*'가정'!$D$46-'가정'!$D$50*($A47)*(2)/'가정'!$D$63*(C$42)*'가정'!$D$49*(1)*'가정'!$D$46-('가정'!$D$72+'가정'!$D$73+'가정'!$D$74))>0,(((1)*('계산'!$C$18+'계산'!$C$19)+'계산'!$C$22)*(1+('가정'!$D$57))*'가정'!$D$46+'가정'!$D$58)/('가정'!$D$12*('가정'!$D$14)*('가정'!$D$15)*('가정'!$D$16)*(2)*('계산'!$C$14)-((1)*'계산'!$C$18+'계산'!$C$22)*('가정'!$D$60)*'가정'!$D$46-'가정'!$D$50*($A47)*(2)/'가정'!$D$63*(C$42)*'가정'!$D$49*(1)*'가정'!$D$46-('가정'!$D$72+'가정'!$D$73+'가정'!$D$74)),"회수 불가") | D47: =IF(('가정'!$D$12*('가정'!$D$14)*('가정'!$D$15)*('가정'!$D$16)*(2)*('계산'!$C$14)-((1)*'계산'!$C$18+'계산'!$C$22)*('가정'!$D$60)*'가정'!$D$46-'가정'!$D$50*($A47)*(2)/'가정'!$D$63*(D$42)*'가정'!$D$49*(1)*'가정'!$D$46-('가정'!$D$72+'가정'!$D$73+'가정'!$D$74))>0,(((1)*('계산'!$C$18+'계산'!$C$19)+'계산'!$C$22)*(1+('가정'!$D$57))*'가정'!$D$46+'가정'!$D$58)/('가정'!$D$12*('가정'!$D$14)*('가정'!$D$15)*('가정'!$D$16)*(2)*('계산'!$C$14)-((1)*'계산'!$C$18+'계산'!$C$22)*('가정'!$D$60)*'가정'!$D$46-'가정'!$D$50*($A47)*(2)/'가정'!$D$63*(D$42)*'가정'!$D$49*(1)*'가정'!$D$46-('가정'!$D$72+'가정'!$D$73+'가정'!$D$74)),"회수 불가") | E47: =IF(('가정'!$D$12*('가정'!$D$14)*('가정'!$D$15)*('가정'!$D$16)*(2)*('계산'!$C$14)-((1)*'계산'!$C$18+'계산'!$C$22)*('가정'!$D$60)*'가정'!$D$46-'가정'!$D$50*($A47)*(2)/'가정'!$D$63*(E$42)*'가정'!$D$49*(1)*'가정'!$D$46-('가정'!$D$72+'가정'!$D$73+'가정'!$D$74))>0,(((1)*('계산'!$C$18+'계산'!$C$19)+'계산'!$C$22)*(1+('가정'!$D$57))*'가정'!$D$46+'가정'!$D$58)/('가정'!$D$12*('가정'!$D$14)*('가정'!$D$15)*('가정'!$D$16)*(2)*('계산'!$C$14)-((1)*'계산'!$C$18+'계산'!$C$22)*('가정'!$D$60)*'가정'!$D$46-'가정'!$D$50*($A47)*(2)/'가정'!$D$63*(E$42)*'가정'!$D$49*(1)*'가정'!$D$46-('가정'!$D$72+'가정'!$D$73+'가정'!$D$74)),"회수 불가")
...

Sheet 검산
A1: 검산 - 시트 수식 결과 vs 별도 Python 계산 vs 연구 문서 값
A2: 'Python 독립 계산'은 .venv/bin/python으로 시트와 별개의 코드로 계산해 붙여 넣은 숫자(수식 아님). '시트 수식'은 계산·가정 시트 링크. 차이가 허용오차(년 0.0005, 원 1,000원) 안이면 일치. '문서 값'은 research/q7, case/analysis.md 7.5절, research/q8의 인용값(반올림)이다.
A4: 검산 항목 | B4: 단위 | C4: Python 독립 계산 | D4: 시트 수식 | E4: 차이 | F4: 판정 | G4: 문서 값 (반올림) | H4: 문서 출처
A5: A. 인건비 환산 (Q8 5절 시나리오)
A6: 연 인건비/인 - 하한 | B6: 원 | C6: 31990916 | D6: ='계산'!C13 | E6: =D6-C6 | F6: =IF(ABS(E6)<=1000,"일치","불일치") | G6: 31990907 | H6: research/q8-wage-inputs.md 5절
A7: 연 인건비/인 - 기본 | B7: 원 | C7: 63764449 | D7: ='계산'!D13 | E7: =D7-C7 | F7: =IF(ABS(E7)<=1000,"일치","불일치") | G7: 63771373 | H7: research/q8-wage-inputs.md 5절
A8: 연 인건비/인 - 상한 | B8: 원 | C8: 74326312 | D8: ='계산'!E13 | E8: =D8-C8 | F8: =IF(ABS(E8)<=1000,"일치","불일치") | G8: 74331947 | H8: research/q8-wage-inputs.md 5절
A9: A2. 문서 값(Q8 5절)과 시트 값의 상대 차이: 하한/기본/상한 (%) | C9: ='계산'!C13/31990907-1 | D9: ='계산'!D13/63771373-1 | E9: ='계산'!E13/74331947-1 | H9: Q8 문서는 야간조 계수를 295.7로 반올림(시트는 209+0.5x173.3=295.65). 차이는 0.01% 안팎
A10: B. Q7 재현 (구 가정: 인건비 4,700만 원, 유지보수 하드웨어 10%, 대체 1.9명)
A11: 회수 기간: N=1 손 전체 (f=0.5, 100%) | B11: 년 | C11: 10.599558 | D11: ='계산'!L56 | E11: =IF(AND(ISNUMBER(C11),ISNUMBER(D11)),D11-C11,IF(C11=D11,0,999)) | F11: =IF(ABS(E11)<=0.0005,"일치","불일치") | G11: 10.6 | H11: Q7 6-2a, analysis.md 7.5절
A12: 회수 기간: N=2 손 전체 (f=1, 100%) | B12: 년 | C12: 77.25043 | D12: ='계산'!M56 | E12: =IF(AND(ISNUMBER(C12),ISNUMBER(D12)),D12-C12,IF(C12=D12,0,999)) | F12: =IF(ABS(E12)<=0.0005,"일치","불일치") | G12: 77.3 | H12: Q7 6-2a (analysis 7.5절 약 77)
A13: 회수 기간: 교체비 0 | B13: 년 | C13: 5.6901532 | D13: ='계산'!N56 | E13: =IF(AND(ISNUMBER(C13),ISNUMBER(D13)),D13-C13,IF(C13=D13,0,999)) | F13: =IF(ABS(E13)<=0.0005,"일치","불일치") | G13: 5.7 | H13: Q7 6-2a, analysis.md 7.5절
A14: 회수 기간: N=2 모듈 20% (f=1) | B14: 년 | C14: 6.9840821 | D14: ='계산'!O56 | E14: =IF(AND(ISNUMBER(C14),ISNUMBER(D14)),D14-C14,IF(C14=D14,0,999)) | F14: =IF(ABS(E14)<=0.0005,"일치","불일치") | G14: 7 | H14: Q7 6-2a
A15: 회수 기간: N=4 모듈 20% (f=2, 기본 시나리오 후보) | B15: 년 | C15: 9.0396885 | D15: ='계산'!P56 | E15: =IF(AND(ISNUMBER(C15),ISNUMBER(D15)),D15-C15,IF(C15=D15,0,999)) | F15: =IF(ABS(E15)<=0.0005,"일치","불일치") | G15: 9 | H15: Q7 6-2a, 6절
A16: 회수 기간: 3교대 N=6 모듈 20% (f=2 x1.5) | B16: 년 | C16: 5.2373866 | D16: ='계산'!Q56 | E16: =IF(AND(ISNUMBER(C16),ISNUMBER(D16)),D16-C16,IF(C16=D16,0,999)) | F16: =IF(ABS(E16)<=0.0005,"일치","불일치") | G16: 5.2 | H16: Q7 6-2b
A17: 회수 기간: 3교대 교체비 0 | B17: 년 | C17: 3.4648439 | D17: ='계산'!R56 | E17: =IF(AND(ISNUMBER(C17),ISNUMBER(D17)),D17-C17,IF(C17=D17,0,999)) | F17: =IF(ABS(E17)<=0.0005,"일치","불일치") | G17: 3.5 | H17: analysis.md 7.5절
